Workbook

Sheet 사용법
B2: 출석부 엑셀 양식
B3: 원생과 받은 돈을 적고, 달마다 누가 냈는지 봅니다. 나중에 출석부 앱으로 그대로 옮길 수 있습니다.
B5: 1. 원생 | C5: 원생 시트에 한 줄에 한 명씩 적습니다. 요일은 "월,수"처럼, 시간은 "16:00"처럼 적습니다.
C6: 동명이인이 있으면 구분 칸에 "월수반"처럼 짧게 구별할 말을 적습니다.
B7: 2. 수납 | C7: 돈을 받을 때마다 한 줄씩 적습니다. 원생·수입구분·결제수단은 칸을 누르면 목록에서 고를 수 있습니다.
C8: 수강월은 "어느 달 수강료인가"입니다. 9월 말에 받은 10월분은 2026-10 으로 적습니다.
C9: 돌려준 돈은 지우지 말고 금액을 -50000 처럼 음수로 한 줄 더 적습니다.
C10: 계좌이체·현금으로 한 번에 10만 원 이상 받으면 달라는 말이 없어도 받은 날부터 5일 안에 현금영수증을 발급합니다.
C11: 학원은 현금영수증 의무발행업종입니다. 교습소·공부방·과외도 보통 그렇지만 사업자등록증의 업종코드로 확인하세요.
C12: 미취학 칸은 교육비 공제 대상 표시입니다. 초등학교 입학 전, 그리고 2026년 납입분부터는 초1·2학년 예체능(음악·미술·무용·체육)이면 예.
B13: 3. 월별 현황 | C13: 위쪽 노란 칸에 연도를 적으면 원생별로 달마다 낸 수강료가 나옵니다.
C14: 빨간 칸은 그 달 수강료보다 덜 받은 곳, 초록 칸은 다 받은 곳입니다.
C15: 새로 온 원생은 처음 낸 달부터, 그만둔 원생은 퇴원일이 든 달까지만 빨갛게 칠합니다. 이번 달은 아직 안 냈으면 빨갛습니다.
C16: 아래 표는 달마다 받은 돈을 결제수단별로 더한 것입니다(받은 날 기준).
B17: 앱으로 옮기기 | C17: 원생 시트를 열고 [파일 → 다른 이름으로 저장 → CSV UTF-8(쉼표로 분리)]로 저장합니다.
C18: 수납 시트도 같은 방법으로 따로 저장합니다(CSV는 한 번에 한 시트만 저장됩니다).
C19: 앱의 [설정 → 가져오기]에서 원생 명단을 먼저, 수납 기록을 그다음에 가져옵니다.
C20: 같은 파일을 두 번 가져와도 같은 기록은 한 번만 들어갑니다.
B21: 주의 | C21: 원생·수납 시트의 첫 줄(머리글)은 고치지 마세요. 앱이 이 글자로 칸을 알아봅니다.
C22: 열 순서를 바꾸거나 열을 더하는 것은 괜찮습니다. 앱은 머리글 이름으로 읽습니다.
B24: 앱에만 있는 것
C25: · 아이패드로 등원·결석을 누르는 출결과 보충 관리
C26: · 신고 일정 알림(사업장현황신고·종합소득세·중간예납)과 현금영수증 빠진 건 모아 보기
C27: · 홈택스 신고용 숫자와 교육비 납입 증명서를 한 번에 뽑기
C28: · 아이폰·아이패드 사이 자동 동기화와 앱 잠금

Sheet 원생
A1: 이름 | B1: 학년 | C1: 요일 | D1: 시작 | E1: 끝 | F1: 월 수강료 | G1: 구분 | H1: 미취학 | I1: 퇴원일

Sheet 수납
A1: 받은날 | B1: 수강월 | C1: 원생 | D1: 구분 | E1: 수입구분 | F1: 금액 | G1: 결제수단 | H1: 현금영수증 | I1: 미취학 | J1: 메모
I2: =IF(C2="","",IFERROR(IF(INDEX(원생!$H$2:$H$501,MATCH(계산!$A2,계산!$E$2:$E$501,0))="예","예",""),""))
I3: =IF(C3="","",IFERROR(IF(INDEX(원생!$H$2:$H$501,MATCH(계산!$A3,계산!$E$2:$E$501,0))="예","예",""),""))
I4: =IF(C4="","",IFERROR(IF(INDEX(원생!$H$2:$H$501,MATCH(계산!$A4,계산!$E$2:$E$501,0))="예","예",""),""))
I5: =IF(C5="","",IFERROR(IF(INDEX(원생!$H$2:$H$501,MATCH(계산!$A5,계산!$E$2:$E$501,0))="예","예",""),""))
I6: =IF(C6="","",IFERROR(IF(INDEX(원생!$H$2:$H$501,MATCH(계산!$A6,계산!$E$2:$E$501,0))="예","예",""),""))
I7: =IF(C7="","",IFERROR(IF(INDEX(원생!$H$2:$H$501,MATCH(계산!$A7,계산!$E$2:$E$501,0))="예","예",""),""))
I8: =IF(C8="","",IFERROR(IF(INDEX(원생!$H$2:$H$501,MATCH(계산!$A8,계산!$E$2:$E$501,0))="예","예",""),""))
I9: =IF(C9="","",IFERROR(IF(INDEX(원생!$H$2:$H$501,MATCH(계산!$A9,계산!$E$2:$E$501,0))="예","예",""),""))
I10: =IF(C10="","",IFERROR(IF(INDEX(원생!$H$2:$H$501,MATCH(계산!$A10,계산!$E$2:$E$501,0))="예","예",""),""))
I11: =IF(C11="","",IFERROR(IF(INDEX(원생!$H$2:$H$501,MATCH(계산!$A11,계산!$E$2:$E$501,0))="예","예",""),""))
I12: =IF(C12="","",IFERROR(IF(INDEX(원생!$H$2:$H$501,MATCH(계산!$A12,계산!$E$2:$E$501,0))="예","예",""),""))
I13: =IF(C13="","",IFERROR(IF(INDEX(원생!$H$2:$H$501,MATCH(계산!$A13,계산!$E$2:$E$501,0))="예","예",""),""))
... I1001: =IF(C1001="","",IFERROR(IF(INDEX(원생!$H$2:$H$501,MATCH(계산!$A1001,계산!$E$2:$E$501,0))="예","예",""),""))

Sheet 월별 현황
A1: 연도 | B1: 2026 | C1: ← 연도를 바꾸면 아래가 다시 계산됩니다. 수강료(수입구분)만 셉니다.
A3: 원생 | B3: 월 수강료 | C3: 1월 | D3: 2월 | E3: 3월 | F3: 4월 | G3: 5월 | H3: 6월 | I3: 7월 | J3: 8월 | K3: 9월 | L3: 10월 | M3: 11월 | N3: 12월
A4: =IF(원생!$A2="","",원생!$A2&IF(원생!$G2="",""," ("&원생!$G2&")")) | B4: =IF(원생!$A2="","",N(원생!$F2)) | C4: =IF(원생!$A2="","",SUMIFS(계산!$C:$C,계산!$A:$A,계산!$E2,계산!$B:$B,$B$1*100+1)) | D4: =IF(원생!$A2="","",SUMIFS(계산!$C:$C,계산!$A:$A,계산!$E2,계산!$B:$B,$B$1*100+2)) | E4: =IF(원생!$A2="","",SUMIFS(계산!$C:$C,계산!$A:$A,계산!$E2,계산!$B:$B,$B$1*100+3)) | F4: =IF(원생!$A2="","",SUMIFS(계산!$C:$C,계산!$A:$A,계산!$E2,계산!$B:$B,$B$1*100+4)) | G4: =IF(원생!$A2="","",SUMIFS(계산!$C:$C,계산!$A:$A,계산!$E2,계산!$B:$B,$B$1*100+5)) | H4: =IF(원생!$A2="","",SUMIFS(계산!$C:$C,계산!$A:$A,계산!$E2,계산!$B:$B,$B$1*100+6)) | I4: =IF(원생!$A2="","",SUMIFS(계산!$C:$C,계산!$A:$A,계산!$E2,계산!$B:$B,$B$1*100+7)) | J4: =IF(원생!$A2="","",SUMIFS(계산!$C:$C,계산!$A:$A,계산!$E2,계산!$B:$B,$B$1*100+8)) | K4: =IF(원생!$A2="","",SUMIFS(계산!$C:$C,계산!$A:$A,계산!$E2,계산!$B:$B,$B$1*100+9)) | L4: =IF(원생!$A2="","",SUMIFS(계산!$C:$C,계산!$A:$A,계산!$E2,계산!$B:$B,$B$1*100+10)) | M4: =IF(원생!$A2="","",SUMIFS(계산!$C:$C,계산!$A:$A,계산!$E2,계산!$B:$B,$B$1*100+11)) | N4: =IF(원생!$A2="","",SUMIFS(계산!$C:$C,계산!$A:$A,계산!$E2,계산!$B:$B,$B$1*100+12)) | O4: =IF(원생!$I2="","",원생!$I2) | P4: =IF($A4="","",IF(AND($B4>0,C4<$B4,DATE($B$1,1,1)<=TODAY(),OR($O4="",$O4>=DATE($B$1,1,1)),OR(COUNTIF($C4:C4,">0")>0,DATE($B$1,1,1)=DATE(YEAR(TODAY()),MONTH(TODAY()),1))),1,0)) | Q4: =IF($A4="","",IF(AND($B4>0,D4<$B4,DATE($B$1,2,1)<=TODAY(),OR($O4="",$O4>=DATE($B$1,2,1)),OR(COUNTIF($C4:D4,">0")>0,DATE($B$1,2,1)=DATE(YEAR(TODAY()),MONTH(TODAY()),1))),1,0)) | R4: =IF($A4="","",IF(AND($B4>0,E4<$B4,DATE($B$1,3,1)<=TODAY(),OR($O4="",$O4>=DATE($B$1,3,1)),OR(COUNTIF($C4:E4,">0")>0,DATE($B$1,3,1)=DATE(YEAR(TODAY()),MONTH(TODAY()),1))),1,0)) | S4: =IF($A4="","",IF(AND($B4>0,F4<$B4,DATE($B$1,4,1)<=TODAY(),OR($O4="",$O4>=DATE($B$1,4,1)),OR(COUNTIF($C4:F4,">0")>0,DATE($B$1,4,1)=DATE(YEAR(TODAY()),MONTH(TODAY()),1))),1,0)) | T4: =IF($A4="","",IF(AND($B4>0,G4<$B4,DATE($B$1,5,1)<=TODAY(),OR($O4="",$O4>=DATE($B$1,5,1)),OR(COUNTIF($C4:G4,">0")>0,DATE($B$1,5,1)=DATE(YEAR(TODAY()),MONTH(TODAY()),1))),1,0)) | U4: =IF($A4="","",IF(AND($B4>0,H4<$B4,DATE($B$1,6,1)<=TODAY(),OR($O4="",$O4>=DATE($B$1,6,1)),OR(COUNTIF($C4:H4,">0")>0,DATE($B$1,6,1)=DATE(YEAR(TODAY()),MONTH(TODAY()),1))),1,0)) | V4: =IF($A4="","",IF(AND($B4>0,I4<$B4,DATE($B$1,7,1)<=TODAY(),OR($O4="",$O4>=DATE($B$1,7,1)),OR(COUNTIF($C4:I4,">0")>0,DATE($B$1,7,1)=DATE(YEAR(TODAY()),MONTH(TODAY()),1))),1,0)) | W4: =IF($A4="","",IF(AND($B4>0,J4<$B4,DATE($B$1,8,1)<=TODAY(),OR($O4="",$O4>=DATE($B$1,8,1)),OR(COUNTIF($C4:J4,">0")>0,DATE($B$1,8,1)=DATE(YEAR(TODAY()),MONTH(TODAY()),1))),1,0)) | X4: =IF($A4="","",IF(AND($B4>0,K4<$B4,DATE($B$1,9,1)<=TODAY(),OR($O4="",$O4>=DATE($B$1,9,1)),OR(COUNTIF($C4:K4,">0")>0,DATE($B$1,9,1)=DATE(YEAR(TODAY()),MONTH(TODAY()),1))),1,0)) | Y4: =IF($A4="","",IF(AND($B4>0,L4<$B4,DATE($B$1,10,1)<=TODAY(),OR($O4="",$O4>=DATE($B$1,10,1)),OR(COUNTIF($C4:L4,">0")>0,DATE($B$1,10,1)=DATE(YEAR(TODAY()),MONTH(TODAY()),1))),1,0)) | Z4: =IF($A4="","",IF(AND($B4>0,M4<$B4,DATE($B$1,11,1)<=TODAY(),OR($O4="",$O4>=DATE($B$1,11,1)),OR(COUNTIF($C4:M4,">0")>0,DATE($B$1,11,1)=DATE(YEAR(TODAY()),MONTH(TODAY()),1))),1,0)) | AA4: =IF($A4="","",IF(AND($B4>0,N4<$B4,DATE($B$1,12,1)<=TODAY(),OR($O4="",$O4>=DATE($B$1,12,1)),OR(COUNTIF($C4:N4,">0")>0,DATE($B$1,12,1)=DATE(YEAR(TODAY()),MONTH(TODAY()),1))),1,0))
A5: =IF(원생!$A3="","",원생!$A3&IF(원생!$G3="",""," ("&원생!$G3&")")) | B5: =IF(원생!$A3="","",N(원생!$F3)) | C5: =IF(원생!$A3="","",SUMIFS(계산!$C:$C,계산!$A:$A,계산!$E3,계산!$B:$B,$B$1*100+1)) | D5: =IF(원생!$A3="","",SUMIFS(계산!$C:$C,계산!$A:$A,계산!$E3,계산!$B:$B,$B$1*100+2)) | E5: =IF(원생!$A3="","",SUMIFS(계산!$C:$C,계산!$A:$A,계산!$E3,계산!$B:$B,$B$1*100+3)) | F5: =IF(원생!$A3="","",SUMIFS(계산!$C:$C,계산!$A:$A,계산!$E3,계산!$B:$B,$B$1*100+4)) | G5: =IF(원생!$A3="","",SUMIFS(계산!$C:$C,계산!$A:$A,계산!$E3,계산!$B:$B,$B$1*100+5)) | H5: =IF(원생!$A3="","",SUMIFS(계산!$C:$C,계산!$A:$A,계산!$E3,계산!$B:$B,$B$1*100+6)) | I5: =IF(원생!$A3="","",SUMIFS(계산!$C:$C,계산!$A:$A,계산!$E3,계산!$B:$B,$B$1*100+7)) | J5: =IF(원생!$A3="","",SUMIFS(계산!$C:$C,계산!$A:$A,계산!$E3,계산!$B:$B,$B$1*100+8)) | K5: =IF(원생!$A3="","",SUMIFS(계산!$C:$C,계산!$A:$A,계산!$E3,계산!$B:$B,$B$1*100+9)) | L5: =IF(원생!$A3="","",SUMIFS(계산!$C:$C,계산!$A:$A,계산!$E3,계산!$B:$B,$B$1*100+10)) | M5: =IF(원생!$A3="","",SUMIFS(계산!$C:$C,계산!$A:$A,계산!$E3,계산!$B:$B,$B$1*100+11)) | N5: =IF(원생!$A3="","",SUMIFS(계산!$C:$C,계산!$A:$A,계산!$E3,계산!$B:$B,$B$1*100+12)) | O5: =IF(원생!$I3="","",원생!$I3) | P5: =IF($A5="","",IF(AND($B5>0,C5<$B5,DATE($B$1,1,1)<=TODAY(),OR($O5="",$O5>=DATE($B$1,1,1)),OR(COUNTIF($C5:C5,">0")>0,DATE($B$1,1,1)=DATE(YEAR(TODAY()),MONTH(TODAY()),1))),1,0)) | Q5: =IF($A5="","",IF(AND($B5>0,D5<$B5,DATE($B$1,2,1)<=TODAY(),OR($O5="",$O5>=DATE($B$1,2,1)),OR(COUNTIF($C5:D5,">0")>0,DATE($B$1,2,1)=DATE(YEAR(TODAY()),MONTH(TODAY()),1))),1,0)) | R5: =IF($A5="","",IF(AND($B5>0,E5<$B5,DATE($B$1,3,1)<=TODAY(),OR($O5="",$O5>=DATE($B$1,3,1)),OR(COUNTIF($C5:E5,">0")>0,DATE($B$1,3,1)=DATE(YEAR(TODAY()),MONTH(TODAY()),1))),1,0)) | S5: =IF($A5="","",IF(AND($B5>0,F5<$B5,DATE($B$1,4,1)<=TODAY(),OR($O5="",$O5>=DATE($B$1,4,1)),OR(COUNTIF($C5:F5,">0")>0,DATE($B$1,4,1)=DATE(YEAR(TODAY()),MONTH(TODAY()),1))),1,0)) | T5: =IF($A5="","",IF(AND($B5>0,G5<$B5,DATE($B$1,5,1)<=TODAY(),OR($O5="",$O5>=DATE($B$1,5,1)),OR(COUNTIF($C5:G5,">0")>0,DATE($B$1,5,1)=DATE(YEAR(TODAY()),MONTH(TODAY()),1))),1,0)) | U5: =IF($A5="","",IF(AND($B5>0,H5<$B5,DATE($B$1,6,1)<=TODAY(),OR($O5="",$O5>=DATE($B$1,6,1)),OR(COUNTIF($C5:H5,">0")>0,DATE($B$1,6,1)=DATE(YEAR(TODAY()),MONTH(TODAY()),1))),1,0)) | V5: =IF($A5="","",IF(AND($B5>0,I5<$B5,DATE($B$1,7,1)<=TODAY(),OR($O5="",$O5>=DATE($B$1,7,1)),OR(COUNTIF($C5:I5,">0")>0,DATE($B$1,7,1)=DATE(YEAR(TODAY()),MONTH(TODAY()),1))),1,0)) | W5: =IF($A5="","",IF(AND($B5>0,J5<$B5,DATE($B$1,8,1)<=TODAY(),OR($O5="",$O5>=DATE($B$1,8,1)),OR(COUNTIF($C5:J5,">0")>0,DATE($B$1,8,1)=DATE(YEAR(TODAY()),MONTH(TODAY()),1))),1,0)) | X5: =IF($A5="","",IF(AND($B5>0,K5<$B5,DATE($B$1,9,1)<=TODAY(),OR($O5="",$O5>=DATE($B$1,9,1)),OR(COUNTIF($C5:K5,">0")>0,DATE($B$1,9,1)=DATE(YEAR(TODAY()),MONTH(TODAY()),1))),1,0)) | Y5: =IF($A5="","",IF(AND($B5>0,L5<$B5,DATE($B$1,10,1)<=TODAY(),OR($O5="",$O5>=DATE($B$1,10,1)),OR(COUNTIF($C5:L5,">0")>0,DATE($B$1,10,1)=DATE(YEAR(TODAY()),MONTH(TODAY()),1))),1,0)) | Z5: =IF($A5="","",IF(AND($B5>0,M5<$B5,DATE($B$1,11,1)<=TODAY(),OR($O5="",$O5>=DATE($B$1,11,1)),OR(COUNTIF($C5:M5,">0")>0,DATE($B$1,11,1)=DATE(YEAR(TODAY()),MONTH(TODAY()),1))),1,0)) | AA5: =IF($A5="","",IF(AND($B5>0,N5<$B5,DATE($B$1,12,1)<=TODAY(),OR($O5="",$O5>=DATE($B$1,12,1)),OR(COUNTIF($C5:N5,">0")>0,DATE($B$1,12,1)=DATE(YEAR(TODAY()),MONTH(TODAY()),1))),1,0))
A6: =IF(원생!$A4="","",원생!$A4&IF(원생!$G4="",""," ("&원생!$G4&")")) | B6: =IF(원생!$A4="","",N(원생!$F4)) | C6: =IF(원생!$A4="","",SUMIFS(계산!$C:$C,계산!$A:$A,계산!$E4,계산!$B:$B,$B$1*100+1)) | D6: =IF(원생!$A4="","",SUMIFS(계산!$C:$C,계산!$A:$A,계산!$E4,계산!$B:$B,$B$1*100+2)) | E6: =IF(원생!$A4="","",SUMIFS(계산!$C:$C,계산!$A:$A,계산!$E4,계산!$B:$B,$B$1*100+3)) | F6: =IF(원생!$A4="","",SUMIFS(계산!$C:$C,계산!$A:$A,계산!$E4,계산!$B:$B,$B$1*100+4)) | G6: =IF(원생!$A4="","",SUMIFS(계산!$C:$C,계산!$A:$A,계산!$E4,계산!$B:$B,$B$1*100+5)) | H6: =IF(원생!$A4="","",SUMIFS(계산!$C:$C,계산!$A:$A,계산!$E4,계산!$B:$B,$B$1*100+6)) | I6: =IF(원생!$A4="","",SUMIFS(계산!$C:$C,계산!$A:$A,계산!$E4,계산!$B:$B,$B$1*100+7)) | J6: =IF(원생!$A4="","",SUMIFS(계산!$C:$C,계산!$A:$A,계산!$E4,계산!$B:$B,$B$1*100+8)) | K6: =IF(원생!$A4="","",SUMIFS(계산!$C:$C,계산!$A:$A,계산!$E4,계산!$B:$B,$B$1*100+9)) | L6: =IF(원생!$A4="","",SUMIFS(계산!$C:$C,계산!$A:$A,계산!$E4,계산!$B:$B,$B$1*100+10)) | M6: =IF(원생!$A4="","",SUMIFS(계산!$C:$C,계산!$A:$A,계산!$E4,계산!$B:$B,$B$1*100+11)) | N6: =IF(원생!$A4="","",SUMIFS(계산!$C:$C,계산!$A:$A,계산!$E4,계산!$B:$B,$B$1*100+12)) | O6: =IF(원생!$I4="","",원생!$I4) | P6: =IF($A6="","",IF(AND($B6>0,C6<$B6,DATE($B$1,1,1)<=TODAY(),OR($O6="",$O6>=DATE($B$1,1,1)),OR(COUNTIF($C6:C6,">0")>0,DATE($B$1,1,1)=DATE(YEAR(TODAY()),MONTH(TODAY()),1))),1,0)) | Q6: =IF($A6="","",IF(AND($B6>0,D6<$B6,DATE($B$1,2,1)<=TODAY(),OR($O6="",$O6>=DATE($B$1,2,1)),OR(COUNTIF($C6:D6,">0")>0,DATE($B$1,2,1)=DATE(YEAR(TODAY()),MONTH(TODAY()),1))),1,0)) | R6: =IF($A6="","",IF(AND($B6>0,E6<$B6,DATE($B$1,3,1)<=TODAY(),OR($O6="",$O6>=DATE($B$1,3,1)),OR(COUNTIF($C6:E6,">0")>0,DATE($B$1,3,1)=DATE(YEAR(TODAY()),MONTH(TODAY()),1))),1,0)) | S6: =IF($A6="","",IF(AND($B6>0,F6<$B6,DATE($B$1,4,1)<=TODAY(),OR($O6="",$O6>=DATE($B$1,4,1)),OR(COUNTIF($C6:F6,">0")>0,DATE($B$1,4,1)=DATE(YEAR(TODAY()),MONTH(TODAY()),1))),1,0)) | T6: =IF($A6="","",IF(AND($B6>0,G6<$B6,DATE($B$1,5,1)<=TODAY(),OR($O6="",$O6>=DATE($B$1,5,1)),OR(COUNTIF($C6:G6,">0")>0,DATE($B$1,5,1)=DATE(YEAR(TODAY()),MONTH(TODAY()),1))),1,0)) | U6: =IF($A6="","",IF(AND($B6>0,H6<$B6,DATE($B$1,6,1)<=TODAY(),OR($O6="",$O6>=DATE($B$1,6,1)),OR(COUNTIF($C6:H6,">0")>0,DATE($B$1,6,1)=DATE(YEAR(TODAY()),MONTH(TODAY()),1))),1,0)) | V6: =IF($A6="","",IF(AND($B6>0,I6<$B6,DATE($B$1,7,1)<=TODAY(),OR($O6="",$O6>=DATE($B$1,7,1)),OR(COUNTIF($C6:I6,">0")>0,DATE($B$1,7,1)=DATE(YEAR(TODAY()),MONTH(TODAY()),1))),1,0)) | W6: =IF($A6="","",IF(AND($B6>0,J6<$B6,DATE($B$1,8,1)<=TODAY(),OR($O6="",$O6>=DATE($B$1,8,1)),OR(COUNTIF($C6:J6,">0")>0,DATE($B$1,8,1)=DATE(YEAR(TODAY()),MONTH(TODAY()),1))),1,0)) | X6: =IF($A6="","",IF(AND($B6>0,K6<$B6,DATE($B$1,9,1)<=TODAY(),OR($O6="",$O6>=DATE($B$1,9,1)),OR(COUNTIF($C6:K6,">0")>0,DATE($B$1,9,1)=DATE(YEAR(TODAY()),MONTH(TODAY()),1))),1,0)) | Y6: =IF($A6="","",IF(AND($B6>0,L6<$B6,DATE($B$1,10,1)<=TODAY(),OR($O6="",$O6>=DATE($B$1,10,1)),OR(COUNTIF($C6:L6,">0")>0,DATE($B$1,10,1)=DATE(YEAR(TODAY()),MONTH(TODAY()),1))),1,0)) | Z6: =IF($A6="","",IF(AND($B6>0,M6<$B6,DATE($B$1,11,1)<=TODAY(),OR($O6="",$O6>=DATE($B$1,11,1)),OR(COUNTIF($C6:M6,">0")>0,DATE($B$1,11,1)=DATE(YEAR(TODAY()),MONTH(TODAY()),1))),1,0)) | AA6: =IF($A6="","",IF(AND($B6>0,N6<$B6,DATE($B$1,12,1)<=TODAY(),OR($O6="",$O6>=DATE($B$1,12,1)),OR(COUNTIF($C6:N6,">0")>0,DATE($B$1,12,1)=DATE(YEAR(TODAY()),MONTH(TODAY()),1))),1,0))
A7: =IF(원생!$A5="","",원생!$A5&IF(원생!$G5="",""," ("&원생!$G5&")")) | B7: =IF(원생!$A5="","",N(원생!$F5)) | C7: =IF(원생!$A5="","",SUMIFS(계산!$C:$C,계산!$A:$A,계산!$E5,계산!$B:$B,$B$1*100+1)) | D7: =IF(원생!$A5="","",SUMIFS(계산!$C:$C,계산!$A:$A,계산!$E5,계산!$B:$B,$B$1*100+2)) | E7: =IF(원생!$A5="","",SUMIFS(계산!$C:$C,계산!$A:$A,계산!$E5,계산!$B:$B,$B$1*100+3)) | F7: =IF(원생!$A5="","",SUMIFS(계산!$C:$C,계산!$A:$A,계산!$E5,계산!$B:$B,$B$1*100+4)) | G7: =IF(원생!$A5="","",SUMIFS(계산!$C:$C,계산!$A:$A,계산!$E5,계산!$B:$B,$B$1*100+5)) | H7: =IF(원생!$A5="","",SUMIFS(계산!$C:$C,계산!$A:$A,계산!$E5,계산!$B:$B,$B$1*100+6)) | I7: =IF(원생!$A5="","",SUMIFS(계산!$C:$C,계산!$A:$A,계산!$E5,계산!$B:$B,$B$1*100+7)) | J7: =IF(원생!$A5="","",SUMIFS(계산!$C:$C,계산!$A:$A,계산!$E5,계산!$B:$B,$B$1*100+8)) | K7: =IF(원생!$A5="","",SUMIFS(계산!$C:$C,계산!$A:$A,계산!$E5,계산!$B:$B,$B$1*100+9)) | L7: =IF(원생!$A5="","",SUMIFS(계산!$C:$C,계산!$A:$A,계산!$E5,계산!$B:$B,$B$1*100+10)) | M7: =IF(원생!$A5="","",SUMIFS(계산!$C:$C,계산!$A:$A,계산!$E5,계산!$B:$B,$B$1*100+11)) | N7: =IF(원생!$A5="","",SUMIFS(계산!$C:$C,계산!$A:$A,계산!$E5,계산!$B:$B,$B$1*100+12)) | O7: =IF(원생!$I5="","",원생!$I5) | P7: =IF($A7="","",IF(AND($B7>0,C7<$B7,DATE($B$1,1,1)<=TODAY(),OR($O7="",$O7>=DATE($B$1,1,1)),OR(COUNTIF($C7:C7,">0")>0,DATE($B$1,1,1)=DATE(YEAR(TODAY()),MONTH(TODAY()),1))),1,0)) | Q7: =IF($A7="","",IF(AND($B7>0,D7<$B7,DATE($B$1,2,1)<=TODAY(),OR($O7="",$O7>=DATE($B$1,2,1)),OR(COUNTIF($C7:D7,">0")>0,DATE($B$1,2,1)=DATE(YEAR(TODAY()),MONTH(TODAY()),1))),1,0)) | R7: =IF($A7="","",IF(AND($B7>0,E7<$B7,DATE($B$1,3,1)<=TODAY(),OR($O7="",$O7>=DATE($B$1,3,1)),OR(COUNTIF($C7:E7,">0")>0,DATE($B$1,3,1)=DATE(YEAR(TODAY()),MONTH(TODAY()),1))),1,0)) | S7: =IF($A7="","",IF(AND($B7>0,F7<$B7,DATE($B$1,4,1)<=TODAY(),OR($O7="",$O7>=DATE($B$1,4,1)),OR(COUNTIF($C7:F7,">0")>0,DATE($B$1,4,1)=DATE(YEAR(TODAY()),MONTH(TODAY()),1))),1,0)) | T7: =IF($A7="","",IF(AND($B7>0,G7<$B7,DATE($B$1,5,1)<=TODAY(),OR($O7="",$O7>=DATE($B$1,5,1)),OR(COUNTIF($C7:G7,">0")>0,DATE($B$1,5,1)=DATE(YEAR(TODAY()),MONTH(TODAY()),1))),1,0)) | U7: =IF($A7="","",IF(AND($B7>0,H7<$B7,DATE($B$1,6,1)<=TODAY(),OR($O7="",$O7>=DATE($B$1,6,1)),OR(COUNTIF($C7:H7,">0")>0,DATE($B$1,6,1)=DATE(YEAR(TODAY()),MONTH(TODAY()),1))),1,0)) | V7: =IF($A7="","",IF(AND($B7>0,I7<$B7,DATE($B$1,7,1)<=TODAY(),OR($O7="",$O7>=DATE($B$1,7,1)),OR(COUNTIF($C7:I7,">0")>0,DATE($B$1,7,1)=DATE(YEAR(TODAY()),MONTH(TODAY()),1))),1,0)) | W7: =IF($A7="","",IF(AND($B7>0,J7<$B7,DATE($B$1,8,1)<=TODAY(),OR($O7="",$O7>=DATE($B$1,8,1)),OR(COUNTIF($C7:J7,">0")>0,DATE($B$1,8,1)=DATE(YEAR(TODAY()),MONTH(TODAY()),1))),1,0)) | X7: =IF($A7="","",IF(AND($B7>0,K7<$B7,DATE($B$1,9,1)<=TODAY(),OR($O7="",$O7>=DATE($B$1,9,1)),OR(COUNTIF($C7:K7,">0")>0,DATE($B$1,9,1)=DATE(YEAR(TODAY()),MONTH(TODAY()),1))),1,0)) | Y7: =IF($A7="","",IF(AND($B7>0,L7<$B7,DATE($B$1,10,1)<=TODAY(),OR($O7="",$O7>=DATE($B$1,10,1)),OR(COUNTIF($C7:L7,">0")>0,DATE($B$1,10,1)=DATE(YEAR(TODAY()),MONTH(TODAY()),1))),1,0)) | Z7: =IF($A7="","",IF(AND($B7>0,M7<$B7,DATE($B$1,11,1)<=TODAY(),OR($O7="",$O7>=DATE($B$1,11,1)),OR(COUNTIF($C7:M7,">0")>0,DATE($B$1,11,1)=DATE(YEAR(TODAY()),MONTH(TODAY()),1))),1,0)) | AA7: =IF($A7="","",IF(AND($B7>0,N7<$B7,DATE($B$1,12,1)<=TODAY(),OR($O7="",$O7>=DATE($B$1,12,1)),OR(COUNTIF($C7:N7,">0")>0,DATE($B$1,12,1)=DATE(YEAR(TODAY()),MONTH(TODAY()),1))),1,0))
A8: =IF(원생!$A6="","",원생!$A6&IF(원생!$G6="",""," ("&원생!$G6&")")) | B8: =IF(원생!$A6="","",N(원생!$F6)) | C8: =IF(원생!$A6="","",SUMIFS(계산!$C:$C,계산!$A:$A,계산!$E6,계산!$B:$B,$B$1*100+1)) | D8: =IF(원생!$A6="","",SUMIFS(계산!$C:$C,계산!$A:$A,계산!$E6,계산!$B:$B,$B$1*100+2)) | E8: =IF(원생!$A6="","",SUMIFS(계산!$C:$C,계산!$A:$A,계산!$E6,계산!$B:$B,$B$1*100+3)) | F8: =IF(원생!$A6="","",SUMIFS(계산!$C:$C,계산!$A:$A,계산!$E6,계산!$B:$B,$B$1*100+4)) | G8: =IF(원생!$A6="","",SUMIFS(계산!$C:$C,계산!$A:$A,계산!$E6,계산!$B:$B,$B$1*100+5)) | H8: =IF(원생!$A6="","",SUMIFS(계산!$C:$C,계산!$A:$A,계산!$E6,계산!$B:$B,$B$1*100+6)) | I8: =IF(원생!$A6="","",SUMIFS(계산!$C:$C,계산!$A:$A,계산!$E6,계산!$B:$B,$B$1*100+7)) | J8: =IF(원생!$A6="","",SUMIFS(계산!$C:$C,계산!$A:$A,계산!$E6,계산!$B:$B,$B$1*100+8)) | K8: =IF(원생!$A6="","",SUMIFS(계산!$C:$C,계산!$A:$A,계산!$E6,계산!$B:$B,$B$1*100+9)) | L8: =IF(원생!$A6="","",SUMIFS(계산!$C:$C,계산!$A:$A,계산!$E6,계산!$B:$B,$B$1*100+10)) | M8: =IF(원생!$A6="","",SUMIFS(계산!$C:$C,계산!$A:$A,계산!$E6,계산!$B:$B,$B$1*100+11)) | N8: =IF(원생!$A6="","",SUMIFS(계산!$C:$C,계산!$A:$A,계산!$E6,계산!$B:$B,$B$1*100+12)) | O8: =IF(원생!$I6="","",원생!$I6) | P8: =IF($A8="","",IF(AND($B8>0,C8<$B8,DATE($B$1,1,1)<=TODAY(),OR($O8="",$O8>=DATE($B$1,1,1)),OR(COUNTIF($C8:C8,">0")>0,DATE($B$1,1,1)=DATE(YEAR(TODAY()),MONTH(TODAY()),1))),1,0)) | Q8: =IF($A8="","",IF(AND($B8>0,D8<$B8,DATE($B$1,2,1)<=TODAY(),OR($O8="",$O8>=DATE($B$1,2,1)),OR(COUNTIF($C8:D8,">0")>0,DATE($B$1,2,1)=DATE(YEAR(TODAY()),MONTH(TODAY()),1))),1,0)) | R8: =IF($A8="","",IF(AND($B8>0,E8<$B8,DATE($B$1,3,1)<=TODAY(),OR($O8="",$O8>=DATE($B$1,3,1)),OR(COUNTIF($C8:E8,">0")>0,DATE($B$1,3,1)=DATE(YEAR(TODAY()),MONTH(TODAY()),1))),1,0)) | S8: =IF($A8="","",IF(AND($B8>0,F8<$B8,DATE($B$1,4,1)<=TODAY(),OR($O8="",$O8>=DATE($B$1,4,1)),OR(COUNTIF($C8:F8,">0")>0,DATE($B$1,4,1)=DATE(YEAR(TODAY()),MONTH(TODAY()),1))),1,0)) | T8: =IF($A8="","",IF(AND($B8>0,G8<$B8,DATE($B$1,5,1)<=TODAY(),OR($O8="",$O8>=DATE($B$1,5,1)),OR(COUNTIF($C8:G8,">0")>0,DATE($B$1,5,1)=DATE(YEAR(TODAY()),MONTH(TODAY()),1))),1,0)) | U8: =IF($A8="","",IF(AND($B8>0,H8<$B8,DATE($B$1,6,1)<=TODAY(),OR($O8="",$O8>=DATE($B$1,6,1)),OR(COUNTIF($C8:H8,">0")>0,DATE($B$1,6,1)=DATE(YEAR(TODAY()),MONTH(TODAY()),1))),1,0)) | V8: =IF($A8="","",IF(AND($B8>0,I8<$B8,DATE($B$1,7,1)<=TODAY(),OR($O8="",$O8>=DATE($B$1,7,1)),OR(COUNTIF($C8:I8,">0")>0,DATE($B$1,7,1)=DATE(YEAR(TODAY()),MONTH(TODAY()),1))),1,0)) | W8: =IF($A8="","",IF(AND($B8>0,J8<$B8,DATE($B$1,8,1)<=TODAY(),OR($O8="",$O8>=DATE($B$1,8,1)),OR(COUNTIF($C8:J8,">0")>0,DATE($B$1,8,1)=DATE(YEAR(TODAY()),MONTH(TODAY()),1))),1,0)) | X8: =IF($A8="","",IF(AND($B8>0,K8<$B8,DATE($B$1,9,1)<=TODAY(),OR($O8="",$O8>=DATE($B$1,9,1)),OR(COUNTIF($C8:K8,">0")>0,DATE($B$1,9,1)=DATE(YEAR(TODAY()),MONTH(TODAY()),1))),1,0)) | Y8: =IF($A8="","",IF(AND($B8>0,L8<$B8,DATE($B$1,10,1)<=TODAY(),OR($O8="",$O8>=DATE($B$1,10,1)),OR(COUNTIF($C8:L8,">0")>0,DATE($B$1,10,1)=DATE(YEAR(TODAY()),MONTH(TODAY()),1))),1,0)) | Z8: =IF($A8="","",IF(AND($B8>0,M8<$B8,DATE($B$1,11,1)<=TODAY(),OR($O8="",$O8>=DATE($B$1,11,1)),OR(COUNTIF($C8:M8,">0")>0,DATE($B$1,11,1)=DATE(YEAR(TODAY()),MONTH(TODAY()),1))),1,0)) | AA8: =IF($A8="","",IF(AND($B8>0,N8<$B8,DATE($B$1,12,1)<=TODAY(),OR($O8="",$O8>=DATE($B$1,12,1)),OR(COUNTIF($C8:N8,">0")>0,DATE($B$1,12,1)=DATE(YEAR(TODAY()),MONTH(TODAY()),1))),1,0))
A9: =IF(원생!$A7="","",원생!$A7&IF(원생!$G7="",""," ("&원생!$G7&")")) | B9: =IF(원생!$A7="","",N(원생!$F7)) | C9: =IF(원생!$A7="","",SUMIFS(계산!$C:$C,계산!$A:$A,계산!$E7,계산!$B:$B,$B$1*100+1)) | D9: =IF(원생!$A7="","",SUMIFS(계산!$C:$C,계산!$A:$A,계산!$E7,계산!$B:$B,$B$1*100+2)) | E9: =IF(원생!$A7="","",SUMIFS(계산!$C:$C,계산!$A:$A,계산!$E7,계산!$B:$B,$B$1*100+3)) | F9: =IF(원생!$A7="","",SUMIFS(계산!$C:$C,계산!$A:$A,계산!$E7,계산!$B:$B,$B$1*100+4)) | G9: =IF(원생!$A7="","",SUMIFS(계산!$C:$C,계산!$A:$A,계산!$E7,계산!$B:$B,$B$1*100+5)) | H9: =IF(원생!$A7="","",SUMIFS(계산!$C:$C,계산!$A:$A,계산!$E7,계산!$B:$B,$B$1*100+6)) | I9: =IF(원생!$A7="","",SUMIFS(계산!$C:$C,계산!$A:$A,계산!$E7,계산!$B:$B,$B$1*100+7)) | J9: =IF(원생!$A7="","",SUMIFS(계산!$C:$C,계산!$A:$A,계산!$E7,계산!$B:$B,$B$1*100+8)) | K9: =IF(원생!$A7="","",SUMIFS(계산!$C:$C,계산!$A:$A,계산!$E7,계산!$B:$B,$B$1*100+9)) | L9: =IF(원생!$A7="","",SUMIFS(계산!$C:$C,계산!$A:$A,계산!$E7,계산!$B:$B,$B$1*100+10)) | M9: =IF(원생!$A7="","",SUMIFS(계산!$C:$C,계산!$A:$A,계산!$E7,계산!$B:$B,$B$1*100+11)) | N9: =IF(원생!$A7="","",SUMIFS(계산!$C:$C,계산!$A:$A,계산!$E7,계산!$B:$B,$B$1*100+12)) | O9: =IF(원생!$I7="","",원생!$I7) | P9: =IF($A9="","",IF(AND($B9>0,C9<$B9,DATE($B$1,1,1)<=TODAY(),OR($O9="",$O9>=DATE($B$1,1,1)),OR(COUNTIF($C9:C9,">0")>0,DATE($B$1,1,1)=DATE(YEAR(TODAY()),MONTH(TODAY()),1))),1,0)) | Q9: =IF($A9="","",IF(AND($B9>0,D9<$B9,DATE($B$1,2,1)<=TODAY(),OR($O9="",$O9>=DATE($B$1,2,1)),OR(COUNTIF($C9:D9,">0")>0,DATE($B$1,2,1)=DATE(YEAR(TODAY()),MONTH(TODAY()),1))),1,0)) | R9: =IF($A9="","",IF(AND($B9>0,E9<$B9,DATE($B$1,3,1)<=TODAY(),OR($O9="",$O9>=DATE($B$1,3,1)),OR(COUNTIF($C9:E9,">0")>0,DATE($B$1,3,1)=DATE(YEAR(TODAY()),MONTH(TODAY()),1))),1,0)) | S9: =IF($A9="","",IF(AND($B9>0,F9<$B9,DATE($B$1,4,1)<=TODAY(),OR($O9="",$O9>=DATE($B$1,4,1)),OR(COUNTIF($C9:F9,">0")>0,DATE($B$1,4,1)=DATE(YEAR(TODAY()),MONTH(TODAY()),1))),1,0)) | T9: =IF($A9="","",IF(AND($B9>0,G9<$B9,DATE($B$1,5,1)<=TODAY(),OR($O9="",$O9>=DATE($B$1,5,1)),OR(COUNTIF($C9:G9,">0")>0,DATE($B$1,5,1)=DATE(YEAR(TODAY()),MONTH(TODAY()),1))),1,0)) | U9: =IF($A9="","",IF(AND($B9>0,H9<$B9,DATE($B$1,6,1)<=TODAY(),OR($O9="",$O9>=DATE($B$1,6,1)),OR(COUNTIF($C9:H9,">0")>0,DATE($B$1,6,1)=DATE(YEAR(TODAY()),MONTH(TODAY()),1))),1,0)) | V9: =IF($A9="","",IF(AND($B9>0,I9<$B9,DATE($B$1,7,1)<=TODAY(),OR($O9="",$O9>=DATE($B$1,7,1)),OR(COUNTIF($C9:I9,">0")>0,DATE($B$1,7,1)=DATE(YEAR(TODAY()),MONTH(TODAY()),1))),1,0)) | W9: =IF($A9="","",IF(AND($B9>0,J9<$B9,DATE($B$1,8,1)<=TODAY(),OR($O9="",$O9>=DATE($B$1,8,1)),OR(COUNTIF($C9:J9,">0")>0,DATE($B$1,8,1)=DATE(YEAR(TODAY()),MONTH(TODAY()),1))),1,0)) | X9: =IF($A9="","",IF(AND($B9>0,K9<$B9,DATE($B$1,9,1)<=TODAY(),OR($O9="",$O9>=DATE($B$1,9,1)),OR(COUNTIF($C9:K9,">0")>0,DATE($B$1,9,1)=DATE(YEAR(TODAY()),MONTH(TODAY()),1))),1,0)) | Y9: =IF($A9="","",IF(AND($B9>0,L9<$B9,DATE($B$1,10,1)<=TODAY(),OR($O9="",$O9>=DATE($B$1,10,1)),OR(COUNTIF($C9:L9,">0")>0,DATE($B$1,10,1)=DATE(YEAR(TODAY()),MONTH(TODAY()),1))),1,0)) | Z9: =IF($A9="","",IF(AND($B9>0,M9<$B9,DATE($B$1,11,1)<=TODAY(),OR($O9="",$O9>=DATE($B$1,11,1)),OR(COUNTIF($C9:M9,">0")>0,DATE($B$1,11,1)=DATE(YEAR(TODAY()),MONTH(TODAY()),1))),1,0)) | AA9: =IF($A9="","",IF(AND($B9>0,N9<$B9,DATE($B$1,12,1)<=TODAY(),OR($O9="",$O9>=DATE($B$1,12,1)),OR(COUNTIF($C9:N9,">0")>0,DATE($B$1,12,1)=DATE(YEAR(TODAY()),MONTH(TODAY()),1))),1,0))
A10: =IF(원생!$A8="","",원생!$A8&IF(원생!$G8="",""," ("&원생!$G8&")")) | B10: =IF(원생!$A8="","",N(원생!$F8)) | C10: =IF(원생!$A8="","",SUMIFS(계산!$C:$C,계산!$A:$A,계산!$E8,계산!$B:$B,$B$1*100+1)) | D10: =IF(원생!$A8="","",SUMIFS(계산!$C:$C,계산!$A:$A,계산!$E8,계산!$B:$B,$B$1*100+2)) | E10: =IF(원생!$A8="","",SUMIFS(계산!$C:$C,계산!$A:$A,계산!$E8,계산!$B:$B,$B$1*100+3)) | F10: =IF(원생!$A8="","",SUMIFS(계산!$C:$C,계산!$A:$A,계산!$E8,계산!$B:$B,$B$1*100+4)) | G10: =IF(원생!$A8="","",SUMIFS(계산!$C:$C,계산!$A:$A,계산!$E8,계산!$B:$B,$B$1*100+5)) | H10: =IF(원생!$A8="","",SUMIFS(계산!$C:$C,계산!$A:$A,계산!$E8,계산!$B:$B,$B$1*100+6)) | I10: =IF(원생!$A8="","",SUMIFS(계산!$C:$C,계산!$A:$A,계산!$E8,계산!$B:$B,$B$1*100+7)) | J10: =IF(원생!$A8="","",SUMIFS(계산!$C:$C,계산!$A:$A,계산!$E8,계산!$B:$B,$B$1*100+8)) | K10: =IF(원생!$A8="","",SUMIFS(계산!$C:$C,계산!$A:$A,계산!$E8,계산!$B:$B,$B$1*100+9)) | L10: =IF(원생!$A8="","",SUMIFS(계산!$C:$C,계산!$A:$A,계산!$E8,계산!$B:$B,$B$1*100+10)) | M10: =IF(원생!$A8="","",SUMIFS(계산!$C:$C,계산!$A:$A,계산!$E8,계산!$B:$B,$B$1*100+11)) | N10: =IF(원생!$A8="","",SUMIFS(계산!$C:$C,계산!$A:$A,계산!$E8,계산!$B:$B,$B$1*100+12)) | O10: =IF(원생!$I8="","",원생!$I8) | P10: =IF($A10="","",IF(AND($B10>0,C10<$B10,DATE($B$1,1,1)<=TODAY(),OR($O10="",$O10>=DATE($B$1,1,1)),OR(COUNTIF($C10:C10,">0")>0,DATE($B$1,1,1)=DATE(YEAR(TODAY()),MONTH(TODAY()),1))),1,0)) | Q10: =IF($A10="","",IF(AND($B10>0,D10<$B10,DATE($B$1,2,1)<=TODAY(),OR($O10="",$O10>=DATE($B$1,2,1)),OR(COUNTIF($C10:D10,">0")>0,DATE($B$1,2,1)=DATE(YEAR(TODAY()),MONTH(TODAY()),1))),1,0)) | R10: =IF($A10="","",IF(AND($B10>0,E10<$B10,DATE($B$1,3,1)<=TODAY(),OR($O10="",$O10>=DATE($B$1,3,1)),OR(COUNTIF($C10:E10,">0")>0,DATE($B$1,3,1)=DATE(YEAR(TODAY()),MONTH(TODAY()),1))),1,0)) | S10: =IF($A10="","",IF(AND($B10>0,F10<$B10,DATE($B$1,4,1)<=TODAY(),OR($O10="",$O10>=DATE($B$1,4,1)),OR(COUNTIF($C10:F10,">0")>0,DATE($B$1,4,1)=DATE(YEAR(TODAY()),MONTH(TODAY()),1))),1,0)) | T10: =IF($A10="","",IF(AND($B10>0,G10<$B10,DATE($B$1,5,1)<=TODAY(),OR($O10="",$O10>=DATE($B$1,5,1)),OR(COUNTIF($C10:G10,">0")>0,DATE($B$1,5,1)=DATE(YEAR(TODAY()),MONTH(TODAY()),1))),1,0)) | U10: =IF($A10="","",IF(AND($B10>0,H10<$B10,DATE($B$1,6,1)<=TODAY(),OR($O10="",$O10>=DATE($B$1,6,1)),OR(COUNTIF($C10:H10,">0")>0,DATE($B$1,6,1)=DATE(YEAR(TODAY()),MONTH(TODAY()),1))),1,0)) | V10: =IF($A10="","",IF(AND($B10>0,I10<$B10,DATE($B$1,7,1)<=TODAY(),OR($O10="",$O10>=DATE($B$1,7,1)),OR(COUNTIF($C10:I10,">0")>0,DATE($B$1,7,1)=DATE(YEAR(TODAY()),MONTH(TODAY()),1))),1,0)) | W10: =IF($A10="","",IF(AND($B10>0,J10<$B10,DATE($B$1,8,1)<=TODAY(),OR($O10="",$O10>=DATE($B$1,8,1)),OR(COUNTIF($C10:J10,">0")>0,DATE($B$1,8,1)=DATE(YEAR(TODAY()),MONTH(TODAY()),1))),1,0)) | X10: =IF($A10="","",IF(AND($B10>0,K10<$B10,DATE($B$1,9,1)<=TODAY(),OR($O10="",$O10>=DATE($B$1,9,1)),OR(COUNTIF($C10:K10,">0")>0,DATE($B$1,9,1)=DATE(YEAR(TODAY()),MONTH(TODAY()),1))),1,0)) | Y10: =IF($A10="","",IF(AND($B10>0,L10<$B10,DATE($B$1,10,1)<=TODAY(),OR($O10="",$O10>=DATE($B$1,10,1)),OR(COUNTIF($C10:L10,">0")>0,DATE($B$1,10,1)=DATE(YEAR(TODAY()),MONTH(TODAY()),1))),1,0)) | Z10: =IF($A10="","",IF(AND($B10>0,M10<$B10,DATE($B$1,11,1)<=TODAY(),OR($O10="",$O10>=DATE($B$1,11,1)),OR(COUNTIF($C10:M10,">0")>0,DATE($B$1,11,1)=DATE(YEAR(TODAY()),MONTH(TODAY()),1))),1,0)) | AA10: =IF($A10="","",IF(AND($B10>0,N10<$B10,DATE($B$1,12,1)<=TODAY(),OR($O10="",$O10>=DATE($B$1,12,1)),OR(COUNTIF($C10:N10,">0")>0,DATE($B$1,12,1)=DATE(YEAR(TODAY()),MONTH(TODAY()),1))),1,0))
A11: =IF(원생!$A9="","",원생!$A9&IF(원생!$G9="",""," ("&원생!$G9&")")) | B11: =IF(원생!$A9="","",N(원생!$F9)) | C11: =IF(원생!$A9="","",SUMIFS(계산!$C:$C,계산!$A:$A,계산!$E9,계산!$B:$B,$B$1*100+1)) | D11: =IF(원생!$A9="","",SUMIFS(계산!$C:$C,계산!$A:$A,계산!$E9,계산!$B:$B,$B$1*100+2)) | E11: =IF(원생!$A9="","",SUMIFS(계산!$C:$C,계산!$A:$A,계산!$E9,계산!$B:$B,$B$1*100+3)) | F11: =IF(원생!$A9="","",SUMIFS(계산!$C:$C,계산!$A:$A,계산!$E9,계산!$B:$B,$B$1*100+4)) | G11: =IF(원생!$A9="","",SUMIFS(계산!$C:$C,계산!$A:$A,계산!$E9,계산!$B:$B,$B$1*100+5)) | H11: =IF(원생!$A9="","",SUMIFS(계산!$C:$C,계산!$A:$A,계산!$E9,계산!$B:$B,$B$1*100+6)) | I11: =IF(원생!$A9="","",SUMIFS(계산!$C:$C,계산!$A:$A,계산!$E9,계산!$B:$B,$B$1*100+7)) | J11: =IF(원생!$A9="","",SUMIFS(계산!$C:$C,계산!$A:$A,계산!$E9,계산!$B:$B,$B$1*100+8)) | K11: =IF(원생!$A9="","",SUMIFS(계산!$C:$C,계산!$A:$A,계산!$E9,계산!$B:$B,$B$1*100+9)) | L11: =IF(원생!$A9="","",SUMIFS(계산!$C:$C,계산!$A:$A,계산!$E9,계산!$B:$B,$B$1*100+10)) | M11: =IF(원생!$A9="","",SUMIFS(계산!$C:$C,계산!$A:$A,계산!$E9,계산!$B:$B,$B$1*100+11)) | N11: =IF(원생!$A9="","",SUMIFS(계산!$C:$C,계산!$A:$A,계산!$E9,계산!$B:$B,$B$1*100+12)) | O11: =IF(원생!$I9="","",원생!$I9) | P11: =IF($A11="","",IF(AND($B11>0,C11<$B11,DATE($B$1,1,1)<=TODAY(),OR($O11="",$O11>=DATE($B$1,1,1)),OR(COUNTIF($C11:C11,">0")>0,DATE($B$1,1,1)=DATE(YEAR(TODAY()),MONTH(TODAY()),1))),1,0)) | Q11: =IF($A11="","",IF(AND($B11>0,D11<$B11,DATE($B$1,2,1)<=TODAY(),OR($O11="",$O11>=DATE($B$1,2,1)),OR(COUNTIF($C11:D11,">0")>0,DATE($B$1,2,1)=DATE(YEAR(TODAY()),MONTH(TODAY()),1))),1,0)) | R11: =IF($A11="","",IF(AND($B11>0,E11<$B11,DATE($B$1,3,1)<=TODAY(),OR($O11="",$O11>=DATE($B$1,3,1)),OR(COUNTIF($C11:E11,">0")>0,DATE($B$1,3,1)=DATE(YEAR(TODAY()),MONTH(TODAY()),1))),1,0)) | S11: =IF($A11="","",IF(AND($B11>0,F11<$B11,DATE($B$1,4,1)<=TODAY(),OR($O11="",$O11>=DATE($B$1,4,1)),OR(COUNTIF($C11:F11,">0")>0,DATE($B$1,4,1)=DATE(YEAR(TODAY()),MONTH(TODAY()),1))),1,0)) | T11: =IF($A11="","",IF(AND($B11>0,G11<$B11,DATE($B$1,5,1)<=TODAY(),OR($O11="",$O11>=DATE($B$1,5,1)),OR(COUNTIF($C11:G11,">0")>0,DATE($B$1,5,1)=DATE(YEAR(TODAY()),MONTH(TODAY()),1))),1,0)) | U11: =IF($A11="","",IF(AND($B11>0,H11<$B11,DATE($B$1,6,1)<=TODAY(),OR($O11="",$O11>=DATE($B$1,6,1)),OR(COUNTIF($C11:H11,">0")>0,DATE($B$1,6,1)=DATE(YEAR(TODAY()),MONTH(TODAY()),1))),1,0)) | V11: =IF($A11="","",IF(AND($B11>0,I11<$B11,DATE($B$1,7,1)<=TODAY(),OR($O11="",$O11>=DATE($B$1,7,1)),OR(COUNTIF($C11:I11,">0")>0,DATE($B$1,7,1)=DATE(YEAR(TODAY()),MONTH(TODAY()),1))),1,0)) | W11: =IF($A11="","",IF(AND($B11>0,J11<$B11,DATE($B$1,8,1)<=TODAY(),OR($O11="",$O11>=DATE($B$1,8,1)),OR(COUNTIF($C11:J11,">0")>0,DATE($B$1,8,1)=DATE(YEAR(TODAY()),MONTH(TODAY()),1))),1,0)) | X11: =IF($A11="","",IF(AND($B11>0,K11<$B11,DATE($B$1,9,1)<=TODAY(),OR($O11="",$O11>=DATE($B$1,9,1)),OR(COUNTIF($C11:K11,">0")>0,DATE($B$1,9,1)=DATE(YEAR(TODAY()),MONTH(TODAY()),1))),1,0)) | Y11: =IF($A11="","",IF(AND($B11>0,L11<$B11,DATE($B$1,10,1)<=TODAY(),OR($O11="",$O11>=DATE($B$1,10,1)),OR(COUNTIF($C11:L11,">0")>0,DATE($B$1,10,1)=DATE(YEAR(TODAY()),MONTH(TODAY()),1))),1,0)) | Z11: =IF($A11="","",IF(AND($B11>0,M11<$B11,DATE($B$1,11,1)<=TODAY(),OR($O11="",$O11>=DATE($B$1,11,1)),OR(COUNTIF($C11:M11,">0")>0,DATE($B$1,11,1)=DATE(YEAR(TODAY()),MONTH(TODAY()),1))),1,0)) | AA11: =IF($A11="","",IF(AND($B11>0,N11<$B11,DATE($B$1,12,1)<=TODAY(),OR($O11="",$O11>=DATE($B$1,12,1)),OR(COUNTIF($C11:N11,">0")>0,DATE($B$1,12,1)=DATE(YEAR(TODAY()),MONTH(TODAY()),1))),1,0))
A12: =IF(원생!$A10="","",원생!$A10&IF(원생!$G10="",""," ("&원생!$G10&")")) | B12: =IF(원생!$A10="","",N(원생!$F10)) | C12: =IF(원생!$A10="","",SUMIFS(계산!$C:$C,계산!$A:$A,계산!$E10,계산!$B:$B,$B$1*100+1)) | D12: =IF(원생!$A10="","",SUMIFS(계산!$C:$C,계산!$A:$A,계산!$E10,계산!$B:$B,$B$1*100+2)) | E12: =IF(원생!$A10="","",SUMIFS(계산!$C:$C,계산!$A:$A,계산!$E10,계산!$B:$B,$B$1*100+3)) | F12: =IF(원생!$A10="","",SUMIFS(계산!$C:$C,계산!$A:$A,계산!$E10,계산!$B:$B,$B$1*100+4)) | G12: =IF(원생!$A10="","",SUMIFS(계산!$C:$C,계산!$A:$A,계산!$E10,계산!$B:$B,$B$1*100+5)) | H12: =IF(원생!$A10="","",SUMIFS(계산!$C:$C,계산!$A:$A,계산!$E10,계산!$B:$B,$B$1*100+6)) | I12: =IF(원생!$A10="","",SUMIFS(계산!$C:$C,계산!$A:$A,계산!$E10,계산!$B:$B,$B$1*100+7)) | J12: =IF(원생!$A10="","",SUMIFS(계산!$C:$C,계산!$A:$A,계산!$E10,계산!$B:$B,$B$1*100+8)) | K12: =IF(원생!$A10="","",SUMIFS(계산!$C:$C,계산!$A:$A,계산!$E10,계산!$B:$B,$B$1*100+9)) | L12: =IF(원생!$A10="","",SUMIFS(계산!$C:$C,계산!$A:$A,계산!$E10,계산!$B:$B,$B$1*100+10)) | M12: =IF(원생!$A10="","",SUMIFS(계산!$C:$C,계산!$A:$A,계산!$E10,계산!$B:$B,$B$1*100+11)) | N12: =IF(원생!$A10="","",SUMIFS(계산!$C:$C,계산!$A:$A,계산!$E10,계산!$B:$B,$B$1*100+12)) | O12: =IF(원생!$I10="","",원생!$I10) | P12: =IF($A12="","",IF(AND($B12>0,C12<$B12,DATE($B$1,1,1)<=TODAY(),OR($O12="",$O12>=DATE($B$1,1,1)),OR(COUNTIF($C12:C12,">0")>0,DATE($B$1,1,1)=DATE(YEAR(TODAY()),MONTH(TODAY()),1))),1,0)) | Q12: =IF($A12="","",IF(AND($B12>0,D12<$B12,DATE($B$1,2,1)<=TODAY(),OR($O12="",$O12>=DATE($B$1,2,1)),OR(COUNTIF($C12:D12,">0")>0,DATE($B$1,2,1)=DATE(YEAR(TODAY()),MONTH(TODAY()),1))),1,0)) | R12: =IF($A12="","",IF(AND($B12>0,E12<$B12,DATE($B$1,3,1)<=TODAY(),OR($O12="",$O12>=DATE($B$1,3,1)),OR(COUNTIF($C12:E12,">0")>0,DATE($B$1,3,1)=DATE(YEAR(TODAY()),MONTH(TODAY()),1))),1,0)) | S12: =IF($A12="","",IF(AND($B12>0,F12<$B12,DATE($B$1,4,1)<=TODAY(),OR($O12="",$O12>=DATE($B$1,4,1)),OR(COUNTIF($C12:F12,">0")>0,DATE($B$1,4,1)=DATE(YEAR(TODAY()),MONTH(TODAY()),1))),1,0)) | T12: =IF($A12="","",IF(AND($B12>0,G12<$B12,DATE($B$1,5,1)<=TODAY(),OR($O12="",$O12>=DATE($B$1,5,1)),OR(COUNTIF($C12:G12,">0")>0,DATE($B$1,5,1)=DATE(YEAR(TODAY()),MONTH(TODAY()),1))),1,0)) | U12: =IF($A12="","",IF(AND($B12>0,H12<$B12,DATE($B$1,6,1)<=TODAY(),OR($O12="",$O12>=DATE($B$1,6,1)),OR(COUNTIF($C12:H12,">0")>0,DATE($B$1,6,1)=DATE(YEAR(TODAY()),MONTH(TODAY()),1))),1,0)) | V12: =IF($A12="","",IF(AND($B12>0,I12<$B12,DATE($B$1,7,1)<=TODAY(),OR($O12="",$O12>=DATE($B$1,7,1)),OR(COUNTIF($C12:I12,">0")>0,DATE($B$1,7,1)=DATE(YEAR(TODAY()),MONTH(TODAY()),1))),1,0)) | W12: =IF($A12="","",IF(AND($B12>0,J12<$B12,DATE($B$1,8,1)<=TODAY(),OR($O12="",$O12>=DATE($B$1,8,1)),OR(COUNTIF($C12:J12,">0")>0,DATE($B$1,8,1)=DATE(YEAR(TODAY()),MONTH(TODAY()),1))),1,0)) | X12: =IF($A12="","",IF(AND($B12>0,K12<$B12,DATE($B$1,9,1)<=TODAY(),OR($O12="",$O12>=DATE($B$1,9,1)),OR(COUNTIF($C12:K12,">0")>0,DATE($B$1,9,1)=DATE(YEAR(TODAY()),MONTH(TODAY()),1))),1,0)) | Y12: =IF($A12="","",IF(AND($B12>0,L12<$B12,DATE($B$1,10,1)<=TODAY(),OR($O12="",$O12>=DATE($B$1,10,1)),OR(COUNTIF($C12:L12,">0")>0,DATE($B$1,10,1)=DATE(YEAR(TODAY()),MONTH(TODAY()),1))),1,0)) | Z12: =IF($A12="","",IF(AND($B12>0,M12<$B12,DATE($B$1,11,1)<=TODAY(),OR($O12="",$O12>=DATE($B$1,11,1)),OR(COUNTIF($C12:M12,">0")>0,DATE($B$1,11,1)=DATE(YEAR(TODAY()),MONTH(TODAY()),1))),1,0)) | AA12: =IF($A12="","",IF(AND($B12>0,N12<$B12,DATE($B$1,12,1)<=TODAY(),OR($O12="",$O12>=DATE($B$1,12,1)),OR(COUNTIF($C12:N12,">0")>0,DATE($B$1,12,1)=DATE(YEAR(TODAY()),MONTH(TODAY()),1))),1,0))
A13: =IF(원생!$A11="","",원생!$A11&IF(원생!$G11="",""," ("&원생!$G11&")")) | B13: =IF(원생!$A11="","",N(원생!$F11)) | C13: =IF(원생!$A11="","",SUMIFS(계산!$C:$C,계산!$A:$A,계산!$E11,계산!$B:$B,$B$1*100+1)) | D13: =IF(원생!$A11="","",SUMIFS(계산!$C:$C,계산!$A:$A,계산!$E11,계산!$B:$B,$B$1*100+2)) | E13: =IF(원생!$A11="","",SUMIFS(계산!$C:$C,계산!$A:$A,계산!$E11,계산!$B:$B,$B$1*100+3)) | F13: =IF(원생!$A11="","",SUMIFS(계산!$C:$C,계산!$A:$A,계산!$E11,계산!$B:$B,$B$1*100+4)) | G13: =IF(원생!$A11="","",SUMIFS(계산!$C:$C,계산!$A:$A,계산!$E11,계산!$B:$B,$B$1*100+5)) | H13: =IF(원생!$A11="","",SUMIFS(계산!$C:$C,계산!$A:$A,계산!$E11,계산!$B:$B,$B$1*100+6)) | I13: =IF(원생!$A11="","",SUMIFS(계산!$C:$C,계산!$A:$A,계산!$E11,계산!$B:$B,$B$1*100+7)) | J13: =IF(원생!$A11="","",SUMIFS(계산!$C:$C,계산!$A:$A,계산!$E11,계산!$B:$B,$B$1*100+8)) | K13: =IF(원생!$A11="","",SUMIFS(계산!$C:$C,계산!$A:$A,계산!$E11,계산!$B:$B,$B$1*100+9)) | L13: =IF(원생!$A11="","",SUMIFS(계산!$C:$C,계산!$A:$A,계산!$E11,계산!$B:$B,$B$1*100+10)) | M13: =IF(원생!$A11="","",SUMIFS(계산!$C:$C,계산!$A:$A,계산!$E11,계산!$B:$B,$B$1*100+11)) | N13: =IF(원생!$A11="","",SUMIFS(계산!$C:$C,계산!$A:$A,계산!$E11,계산!$B:$B,$B$1*100+12)) | O13: =IF(원생!$I11="","",원생!$I11) | P13: =IF($A13="","",IF(AND($B13>0,C13<$B13,DATE($B$1,1,1)<=TODAY(),OR($O13="",$O13>=DATE($B$1,1,1)),OR(COUNTIF($C13:C13,">0")>0,DATE($B$1,1,1)=DATE(YEAR(TODAY()),MONTH(TODAY()),1))),1,0)) | Q13: =IF($A13="","",IF(AND($B13>0,D13<$B13,DATE($B$1,2,1)<=TODAY(),OR($O13="",$O13>=DATE($B$1,2,1)),OR(COUNTIF($C13:D13,">0")>0,DATE($B$1,2,1)=DATE(YEAR(TODAY()),MONTH(TODAY()),1))),1,0)) | R13: =IF($A13="","",IF(AND($B13>0,E13<$B13,DATE($B$1,3,1)<=TODAY(),OR($O13="",$O13>=DATE($B$1,3,1)),OR(COUNTIF($C13:E13,">0")>0,DATE($B$1,3,1)=DATE(YEAR(TODAY()),MONTH(TODAY()),1))),1,0)) | S13: =IF($A13="","",IF(AND($B13>0,F13<$B13,DATE($B$1,4,1)<=TODAY(),OR($O13="",$O13>=DATE($B$1,4,1)),OR(COUNTIF($C13:F13,">0")>0,DATE($B$1,4,1)=DATE(YEAR(TODAY()),MONTH(TODAY()),1))),1,0)) | T13: =IF($A13="","",IF(AND($B13>0,G13<$B13,DATE($B$1,5,1)<=TODAY(),OR($O13="",$O13>=DATE($B$1,5,1)),OR(COUNTIF($C13:G13,">0")>0,DATE($B$1,5,1)=DATE(YEAR(TODAY()),MONTH(TODAY()),1))),1,0)) | U13: =IF($A13="","",IF(AND($B13>0,H13<$B13,DATE($B$1,6,1)<=TODAY(),OR($O13="",$O13>=DATE($B$1,6,1)),OR(COUNTIF($C13:H13,">0")>0,DATE($B$1,6,1)=DATE(YEAR(TODAY()),MONTH(TODAY()),1))),1,0)) | V13: =IF($A13="","",IF(AND($B13>0,I13<$B13,DATE($B$1,7,1)<=TODAY(),OR($O13="",$O13>=DATE($B$1,7,1)),OR(COUNTIF($C13:I13,">0")>0,DATE($B$1,7,1)=DATE(YEAR(TODAY()),MONTH(TODAY()),1))),1,0)) | W13: =IF($A13="","",IF(AND($B13>0,J13<$B13,DATE($B$1,8,1)<=TODAY(),OR($O13="",$O13>=DATE($B$1,8,1)),OR(COUNTIF($C13:J13,">0")>0,DATE($B$1,8,1)=DATE(YEAR(TODAY()),MONTH(TODAY()),1))),1,0)) | X13: =IF($A13="","",IF(AND($B13>0,K13<$B13,DATE($B$1,9,1)<=TODAY(),OR($O13="",$O13>=DATE($B$1,9,1)),OR(COUNTIF($C13:K13,">0")>0,DATE($B$1,9,1)=DATE(YEAR(TODAY()),MONTH(TODAY()),1))),1,0)) | Y13: =IF($A13="","",IF(AND($B13>0,L13<$B13,DATE($B$1,10,1)<=TODAY(),OR($O13="",$O13>=DATE($B$1,10,1)),OR(COUNTIF($C13:L13,">0")>0,DATE($B$1,10,1)=DATE(YEAR(TODAY()),MONTH(TODAY()),1))),1,0)) | Z13: =IF($A13="","",IF(AND($B13>0,M13<$B13,DATE($B$1,11,1)<=TODAY(),OR($O13="",$O13>=DATE($B$1,11,1)),OR(COUNTIF($C13:M13,">0")>0,DATE($B$1,11,1)=DATE(YEAR(TODAY()),MONTH(TODAY()),1))),1,0)) | AA13: =IF($A13="","",IF(AND($B13>0,N13<$B13,DATE($B$1,12,1)<=TODAY(),OR($O13="",$O13>=DATE($B$1,12,1)),OR(COUNTIF($C13:N13,">0")>0,DATE($B$1,12,1)=DATE(YEAR(TODAY()),MONTH(TODAY()),1))),1,0))
A14: =IF(원생!$A12="","",원생!$A12&IF(원생!$G12="",""," ("&원생!$G12&")")) | B14: =IF(원생!$A12="","",N(원생!$F12)) | C14: =IF(원생!$A12="","",SUMIFS(계산!$C:$C,계산!$A:$A,계산!$E12,계산!$B:$B,$B$1*100+1)) | D14: =IF(원생!$A12="","",SUMIFS(계산!$C:$C,계산!$A:$A,계산!$E12,계산!$B:$B,$B$1*100+2)) | E14: =IF(원생!$A12="","",SUMIFS(계산!$C:$C,계산!$A:$A,계산!$E12,계산!$B:$B,$B$1*100+3)) | F14: =IF(원생!$A12="","",SUMIFS(계산!$C:$C,계산!$A:$A,계산!$E12,계산!$B:$B,$B$1*100+4)) | G14: =IF(원생!$A12="","",SUMIFS(계산!$C:$C,계산!$A:$A,계산!$E12,계산!$B:$B,$B$1*100+5)) | H14: =IF(원생!$A12="","",SUMIFS(계산!$C:$C,계산!$A:$A,계산!$E12,계산!$B:$B,$B$1*100+6)) | I14: =IF(원생!$A12="","",SUMIFS(계산!$C:$C,계산!$A:$A,계산!$E12,계산!$B:$B,$B$1*100+7)) | J14: =IF(원생!$A12="","",SUMIFS(계산!$C:$C,계산!$A:$A,계산!$E12,계산!$B:$B,$B$1*100+8)) | K14: =IF(원생!$A12="","",SUMIFS(계산!$C:$C,계산!$A:$A,계산!$E12,계산!$B:$B,$B$1*100+9)) | L14: =IF(원생!$A12="","",SUMIFS(계산!$C:$C,계산!$A:$A,계산!$E12,계산!$B:$B,$B$1*100+10)) | M14: =IF(원생!$A12="","",SUMIFS(계산!$C:$C,계산!$A:$A,계산!$E12,계산!$B:$B,$B$1*100+11)) | N14: =IF(원생!$A12="","",SUMIFS(계산!$C:$C,계산!$A:$A,계산!$E12,계산!$B:$B,$B$1*100+12)) | O14: =IF(원생!$I12="","",원생!$I12) | P14: =IF($A14="","",IF(AND($B14>0,C14<$B14,DATE($B$1,1,1)<=TODAY(),OR($O14="",$O14>=DATE($B$1,1,1)),OR(COUNTIF($C14:C14,">0")>0,DATE($B$1,1,1)=DATE(YEAR(TODAY()),MONTH(TODAY()),1))),1,0)) | Q14: =IF($A14="","",IF(AND($B14>0,D14<$B14,DATE($B$1,2,1)<=TODAY(),OR($O14="",$O14>=DATE($B$1,2,1)),OR(COUNTIF($C14:D14,">0")>0,DATE($B$1,2,1)=DATE(YEAR(TODAY()),MONTH(TODAY()),1))),1,0)) | R14: =IF($A14="","",IF(AND($B14>0,E14<$B14,DATE($B$1,3,1)<=TODAY(),OR($O14="",$O14>=DATE($B$1,3,1)),OR(COUNTIF($C14:E14,">0")>0,DATE($B$1,3,1)=DATE(YEAR(TODAY()),MONTH(TODAY()),1))),1,0)) | S14: =IF($A14="","",IF(AND($B14>0,F14<$B14,DATE($B$1,4,1)<=TODAY(),OR($O14="",$O14>=DATE($B$1,4,1)),OR(COUNTIF($C14:F14,">0")>0,DATE($B$1,4,1)=DATE(YEAR(TODAY()),MONTH(TODAY()),1))),1,0)) | T14: =IF($A14="","",IF(AND($B14>0,G14<$B14,DATE($B$1,5,1)<=TODAY(),OR($O14="",$O14>=DATE($B$1,5,1)),OR(COUNTIF($C14:G14,">0")>0,DATE($B$1,5,1)=DATE(YEAR(TODAY()),MONTH(TODAY()),1))),1,0)) | U14: =IF($A14="","",IF(AND($B14>0,H14<$B14,DATE($B$1,6,1)<=TODAY(),OR($O14="",$O14>=DATE($B$1,6,1)),OR(COUNTIF($C14:H14,">0")>0,DATE($B$1,6,1)=DATE(YEAR(TODAY()),MONTH(TODAY()),1))),1,0)) | V14: =IF($A14="","",IF(AND($B14>0,I14<$B14,DATE($B$1,7,1)<=TODAY(),OR($O14="",$O14>=DATE($B$1,7,1)),OR(COUNTIF($C14:I14,">0")>0,DATE($B$1,7,1)=DATE(YEAR(TODAY()),MONTH(TODAY()),1))),1,0)) | W14: =IF($A14="","",IF(AND($B14>0,J14<$B14,DATE($B$1,8,1)<=TODAY(),OR($O14="",$O14>=DATE($B$1,8,1)),OR(COUNTIF($C14:J14,">0")>0,DATE($B$1,8,1)=DATE(YEAR(TODAY()),MONTH(TODAY()),1))),1,0)) | X14: =IF($A14="","",IF(AND($B14>0,K14<$B14,DATE($B$1,9,1)<=TODAY(),OR($O14="",$O14>=DATE($B$1,9,1)),OR(COUNTIF($C14:K14,">0")>0,DATE($B$1,9,1)=DATE(YEAR(TODAY()),MONTH(TODAY()),1))),1,0)) | Y14: =IF($A14="","",IF(AND($B14>0,L14<$B14,DATE($B$1,10,1)<=TODAY(),OR($O14="",$O14>=DATE($B$1,10,1)),OR(COUNTIF($C14:L14,">0")>0,DATE($B$1,10,1)=DATE(YEAR(TODAY()),MONTH(TODAY()),1))),1,0)) | Z14: =IF($A14="","",IF(AND($B14>0,M14<$B14,DATE($B$1,11,1)<=TODAY(),OR($O14="",$O14>=DATE($B$1,11,1)),OR(COUNTIF($C14:M14,">0")>0,DATE($B$1,11,1)=DATE(YEAR(TODAY()),MONTH(TODAY()),1))),1,0)) | AA14: =IF($A14="","",IF(AND($B14>0,N14<$B14,DATE($B$1,12,1)<=TODAY(),OR($O14="",$O14>=DATE($B$1,12,1)),OR(COUNTIF($C14:N14,">0")>0,DATE($B$1,12,1)=DATE(YEAR(TODAY()),MONTH(TODAY()),1))),1,0))
A15: =IF(원생!$A13="","",원생!$A13&IF(원생!$G13="",""," ("&원생!$G13&")")) | B15: =IF(원생!$A13="","",N(원생!$F13)) | C15: =IF(원생!$A13="","",SUMIFS(계산!$C:$C,계산!$A:$A,계산!$E13,계산!$B:$B,$B$1*100+1)) | D15: =IF(원생!$A13="","",SUMIFS(계산!$C:$C,계산!$A:$A,계산!$E13,계산!$B:$B,$B$1*100+2)) | E15: =IF(원생!$A13="","",SUMIFS(계산!$C:$C,계산!$A:$A,계산!$E13,계산!$B:$B,$B$1*100+3)) | F15: =IF(원생!$A13="","",SUMIFS(계산!$C:$C,계산!$A:$A,계산!$E13,계산!$B:$B,$B$1*100+4)) | G15: =IF(원생!$A13="","",SUMIFS(계산!$C:$C,계산!$A:$A,계산!$E13,계산!$B:$B,$B$1*100+5)) | H15: =IF(원생!$A13="","",SUMIFS(계산!$C:$C,계산!$A:$A,계산!$E13,계산!$B:$B,$B$1*100+6)) | I15: =IF(원생!$A13="","",SUMIFS(계산!$C:$C,계산!$A:$A,계산!$E13,계산!$B:$B,$B$1*100+7)) | J15: =IF(원생!$A13="","",SUMIFS(계산!$C:$C,계산!$A:$A,계산!$E13,계산!$B:$B,$B$1*100+8)) | K15: =IF(원생!$A13="","",SUMIFS(계산!$C:$C,계산!$A:$A,계산!$E13,계산!$B:$B,$B$1*100+9)) | L15: =IF(원생!$A13="","",SUMIFS(계산!$C:$C,계산!$A:$A,계산!$E13,계산!$B:$B,$B$1*100+10)) | M15: =IF(원생!$A13="","",SUMIFS(계산!$C:$C,계산!$A:$A,계산!$E13,계산!$B:$B,$B$1*100+11)) | N15: =IF(원생!$A13="","",SUMIFS(계산!$C:$C,계산!$A:$A,계산!$E13,계산!$B:$B,$B$1*100+12)) | O15: =IF(원생!$I13="","",원생!$I13) | P15: =IF($A15="","",IF(AND($B15>0,C15<$B15,DATE($B$1,1,1)<=TODAY(),OR($O15="",$O15>=DATE($B$1,1,1)),OR(COUNTIF($C15:C15,">0")>0,DATE($B$1,1,1)=DATE(YEAR(TODAY()),MONTH(TODAY()),1))),1,0)) | Q15: =IF($A15="","",IF(AND($B15>0,D15<$B15,DATE($B$1,2,1)<=TODAY(),OR($O15="",$O15>=DATE($B$1,2,1)),OR(COUNTIF($C15:D15,">0")>0,DATE($B$1,2,1)=DATE(YEAR(TODAY()),MONTH(TODAY()),1))),1,0)) | R15: =IF($A15="","",IF(AND($B15>0,E15<$B15,DATE($B$1,3,1)<=TODAY(),OR($O15="",$O15>=DATE($B$1,3,1)),OR(COUNTIF($C15:E15,">0")>0,DATE($B$1,3,1)=DATE(YEAR(TODAY()),MONTH(TODAY()),1))),1,0)) | S15: =IF($A15="","",IF(AND($B15>0,F15<$B15,DATE($B$1,4,1)<=TODAY(),OR($O15="",$O15>=DATE($B$1,4,1)),OR(COUNTIF($C15:F15,">0")>0,DATE($B$1,4,1)=DATE(YEAR(TODAY()),MONTH(TODAY()),1))),1,0)) | T15: =IF($A15="","",IF(AND($B15>0,G15<$B15,DATE($B$1,5,1)<=TODAY(),OR($O15="",$O15>=DATE($B$1,5,1)),OR(COUNTIF($C15:G15,">0")>0,DATE($B$1,5,1)=DATE(YEAR(TODAY()),MONTH(TODAY()),1))),1,0)) | U15: =IF($A15="","",IF(AND($B15>0,H15<$B15,DATE($B$1,6,1)<=TODAY(),OR($O15="",$O15>=DATE($B$1,6,1)),OR(COUNTIF($C15:H15,">0")>0,DATE($B$1,6,1)=DATE(YEAR(TODAY()),MONTH(TODAY()),1))),1,0)) | V15: =IF($A15="","",IF(AND($B15>0,I15<$B15,DATE($B$1,7,1)<=TODAY(),OR($O15="",$O15>=DATE($B$1,7,1)),OR(COUNTIF($C15:I15,">0")>0,DATE($B$1,7,1)=DATE(YEAR(TODAY()),MONTH(TODAY()),1))),1,0)) | W15: =IF($A15="","",IF(AND($B15>0,J15<$B15,DATE($B$1,8,1)<=TODAY(),OR($O15="",$O15>=DATE($B$1,8,1)),OR(COUNTIF($C15:J15,">0")>0,DATE($B$1,8,1)=DATE(YEAR(TODAY()),MONTH(TODAY()),1))),1,0)) | X15: =IF($A15="","",IF(AND($B15>0,K15<$B15,DATE($B$1,9,1)<=TODAY(),OR($O15="",$O15>=DATE($B$1,9,1)),OR(COUNTIF($C15:K15,">0")>0,DATE($B$1,9,1)=DATE(YEAR(TODAY()),MONTH(TODAY()),1))),1,0)) | Y15: =IF($A15="","",IF(AND($B15>0,L15<$B15,DATE($B$1,10,1)<=TODAY(),OR($O15="",$O15>=DATE($B$1,10,1)),OR(COUNTIF($C15:L15,">0")>0,DATE($B$1,10,1)=DATE(YEAR(TODAY()),MONTH(TODAY()),1))),1,0)) | Z15: =IF($A15="","",IF(AND($B15>0,M15<$B15,DATE($B$1,11,1)<=TODAY(),OR($O15="",$O15>=DATE($B$1,11,1)),OR(COUNTIF($C15:M15,">0")>0,DATE($B$1,11,1)=DATE(YEAR(TODAY()),MONTH(TODAY()),1))),1,0)) | AA15: =IF($A15="","",IF(AND($B15>0,N15<$B15,DATE($B$1,12,1)<=TODAY(),OR($O15="",$O15>=DATE($B$1,12,1)),OR(COUNTIF($C15:N15,">0")>0,DATE($B$1,12,1)=DATE(YEAR(TODAY()),MONTH(TODAY()),1))),1,0))
... A503: =IF(원생!$A501="","",원생!$A501&IF(원생!$G501="",""," ("&원생!$G501&")")) | B503: =IF(원생!$A501="","",N(원생!$F501)) | C503: =IF(원생!$A501="","",SUMIFS(계산!$C:$C,계산!$A:$A,계산!$E501,계산!$B:$B,$B$1*100+1)) | D503: =IF(원생!$A501="","",SUMIFS(계산!$C:$C,계산!$A:$A,계산!$E501,계산!$B:$B,$B$1*100+2)) | E503: =IF(원생!$A501="","",SUMIFS(계산!$C:$C,계산!$A:$A,계산!$E501,계산!$B:$B,$B$1*100+3)) | F503: =IF(원생!$A501="","",SUMIFS(계산!$C:$C,계산!$A:$A,계산!$E501,계산!$B:$B,$B$1*100+4)) | G503: =IF(원생!$A501="","",SUMIFS(계산!$C:$C,계산!$A:$A,계산!$E501,계산!$B:$B,$B$1*100+5)) | H503: =IF(원생!$A501="","",SUMIFS(계산!$C:$C,계산!$A:$A,계산!$E501,계산!$B:$B,$B$1*100+6)) | I503: =IF(원생!$A501="","",SUMIFS(계산!$C:$C,계산!$A:$A,계산!$E501,계산!$B:$B,$B$1*100+7)) | J503: =IF(원생!$A501="","",SUMIFS(계산!$C:$C,계산!$A:$A,계산!$E501,계산!$B:$B,$B$1*100+8)) | K503: =IF(원생!$A501="","",SUMIFS(계산!$C:$C,계산!$A:$A,계산!$E501,계산!$B:$B,$B$1*100+9)) | L503: =IF(원생!$A501="","",SUMIFS(계산!$C:$C,계산!$A:$A,계산!$E501,계산!$B:$B,$B$1*100+10)) | M503: =IF(원생!$A501="","",SUMIFS(계산!$C:$C,계산!$A:$A,계산!$E501,계산!$B:$B,$B$1*100+11)) | N503: =IF(원생!$A501="","",SUMIFS(계산!$C:$C,계산!$A:$A,계산!$E501,계산!$B:$B,$B$1*100+12)) | O503: =IF(원생!$I501="","",원생!$I501) | P503: =IF($A503="","",IF(AND($B503>0,C503<$B503,DATE($B$1,1,1)<=TODAY(),OR($O503="",$O503>=DATE($B$1,1,1)),OR(COUNTIF($C503:C503,">0")>0,DATE($B$1,1,1)=DATE(YEAR(TODAY()),MONTH(TODAY()),1))),1,0)) | Q503: =IF($A503="","",IF(AND($B503>0,D503<$B503,DATE($B$1,2,1)<=TODAY(),OR($O503="",$O503>=DATE($B$1,2,1)),OR(COUNTIF($C503:D503,">0")>0,DATE($B$1,2,1)=DATE(YEAR(TODAY()),MONTH(TODAY()),1))),1,0)) | R503: =IF($A503="","",IF(AND($B503>0,E503<$B503,DATE($B$1,3,1)<=TODAY(),OR($O503="",$O503>=DATE($B$1,3,1)),OR(COUNTIF($C503:E503,">0")>0,DATE($B$1,3,1)=DATE(YEAR(TODAY()),MONTH(TODAY()),1))),1,0)) | S503: =IF($A503="","",IF(AND($B503>0,F503<$B503,DATE($B$1,4,1)<=TODAY(),OR($O503="",$O503>=DATE($B$1,4,1)),OR(COUNTIF($C503:F503,">0")>0,DATE($B$1,4,1)=DATE(YEAR(TODAY()),MONTH(TODAY()),1))),1,0)) | T503: =IF($A503="","",IF(AND($B503>0,G503<$B503,DATE($B$1,5,1)<=TODAY(),OR($O503="",$O503>=DATE($B$1,5,1)),OR(COUNTIF($C503:G503,">0")>0,DATE($B$1,5,1)=DATE(YEAR(TODAY()),MONTH(TODAY()),1))),1,0)) | U503: =IF($A503="","",IF(AND($B503>0,H503<$B503,DATE($B$1,6,1)<=TODAY(),OR($O503="",$O503>=DATE($B$1,6,1)),OR(COUNTIF($C503:H503,">0")>0,DATE($B$1,6,1)=DATE(YEAR(TODAY()),MONTH(TODAY()),1))),1,0)) | V503: =IF($A503="","",IF(AND($B503>0,I503<$B503,DATE($B$1,7,1)<=TODAY(),OR($O503="",$O503>=DATE($B$1,7,1)),OR(COUNTIF($C503:I503,">0")>0,DATE($B$1,7,1)=DATE(YEAR(TODAY()),MONTH(TODAY()),1))),1,0)) | W503: =IF($A503="","",IF(AND($B503>0,J503<$B503,DATE($B$1,8,1)<=TODAY(),OR($O503="",$O503>=DATE($B$1,8,1)),OR(COUNTIF($C503:J503,">0")>0,DATE($B$1,8,1)=DATE(YEAR(TODAY()),MONTH(TODAY()),1))),1,0)) | X503: =IF($A503="","",IF(AND($B503>0,K503<$B503,DATE($B$1,9,1)<=TODAY(),OR($O503="",$O503>=DATE($B$1,9,1)),OR(COUNTIF($C503:K503,">0")>0,DATE($B$1,9,1)=DATE(YEAR(TODAY()),MONTH(TODAY()),1))),1,0)) | Y503: =IF($A503="","",IF(AND($B503>0,L503<$B503,DATE($B$1,10,1)<=TODAY(),OR($O503="",$O503>=DATE($B$1,10,1)),OR(COUNTIF($C503:L503,">0")>0,DATE($B$1,10,1)=DATE(YEAR(TODAY()),MONTH(TODAY()),1))),1,0)) | Z503: =IF($A503="","",IF(AND($B503>0,M503<$B503,DATE($B$1,11,1)<=TODAY(),OR($O503="",$O503>=DATE($B$1,11,1)),OR(COUNTIF($C503:M503,">0")>0,DATE($B$1,11,1)=DATE(YEAR(TODAY()),MONTH(TODAY()),1))),1,0)) | AA503: =IF($A503="","",IF(AND($B503>0,N503<$B503,DATE($B$1,12,1)<=TODAY(),OR($O503="",$O503>=DATE($B$1,12,1)),OR(COUNTIF($C503:N503,">0")>0,DATE($B$1,12,1)=DATE(YEAR(TODAY()),MONTH(TODAY()),1))),1,0))
A506: 월별 받은 돈 (받은 날 기준, 수입구분 전체)
C507: 1월 | D507: 2월 | E507: 3월 | F507: 4월 | G507: 5월 | H507: 6월 | I507: 7월 | J507: 8월 | K507: 9월 | L507: 10월 | M507: 11월 | N507: 12월
A508: 카드 | C508: =SUMIFS(수납!$F:$F,수납!$A:$A,">="&DATE($B$1,1,1),수납!$A:$A,"<"&DATE($B$1,2,1),수납!$G:$G,"카드") | D508: =SUMIFS(수납!$F:$F,수납!$A:$A,">="&DATE($B$1,2,1),수납!$A:$A,"<"&DATE($B$1,3,1),수납!$G:$G,"카드") | E508: =SUMIFS(수납!$F:$F,수납!$A:$A,">="&DATE($B$1,3,1),수납!$A:$A,"<"&DATE($B$1,4,1),수납!$G:$G,"카드") | F508: =SUMIFS(수납!$F:$F,수납!$A:$A,">="&DATE($B$1,4,1),수납!$A:$A,"<"&DATE($B$1,5,1),수납!$G:$G,"카드") | G508: =SUMIFS(수납!$F:$F,수납!$A:$A,">="&DATE($B$1,5,1),수납!$A:$A,"<"&DATE($B$1,6,1),수납!$G:$G,"카드") | H508: =SUMIFS(수납!$F:$F,수납!$A:$A,">="&DATE($B$1,6,1),수납!$A:$A,"<"&DATE($B$1,7,1),수납!$G:$G,"카드") | I508: =SUMIFS(수납!$F:$F,수납!$A:$A,">="&DATE($B$1,7,1),수납!$A:$A,"<"&DATE($B$1,8,1),수납!$G:$G,"카드") | J508: =SUMIFS(수납!$F:$F,수납!$A:$A,">="&DATE($B$1,8,1),수납!$A:$A,"<"&DATE($B$1,9,1),수납!$G:$G,"카드") | K508: =SUMIFS(수납!$F:$F,수납!$A:$A,">="&DATE($B$1,9,1),수납!$A:$A,"<"&DATE($B$1,10,1),수납!$G:$G,"카드") | L508: =SUMIFS(수납!$F:$F,수납!$A:$A,">="&DATE($B$1,10,1),수납!$A:$A,"<"&DATE($B$1,11,1),수납!$G:$G,"카드") | M508: =SUMIFS(수납!$F:$F,수납!$A:$A,">="&DATE($B$1,11,1),수납!$A:$A,"<"&DATE($B$1,12,1),수납!$G:$G,"카드") | N508: =SUMIFS(수납!$F:$F,수납!$A:$A,">="&DATE($B$1,12,1),수납!$A:$A,"<"&DATE($B$1+1,1,1),수납!$G:$G,"카드")
A509: 계좌이체 | C509: =SUMIFS(수납!$F:$F,수납!$A:$A,">="&DATE($B$1,1,1),수납!$A:$A,"<"&DATE($B$1,2,1),수납!$G:$G,"계좌이체") | D509: =SUMIFS(수납!$F:$F,수납!$A:$A,">="&DATE($B$1,2,1),수납!$A:$A,"<"&DATE($B$1,3,1),수납!$G:$G,"계좌이체") | E509: =SUMIFS(수납!$F:$F,수납!$A:$A,">="&DATE($B$1,3,1),수납!$A:$A,"<"&DATE($B$1,4,1),수납!$G:$G,"계좌이체") | F509: =SUMIFS(수납!$F:$F,수납!$A:$A,">="&DATE($B$1,4,1),수납!$A:$A,"<"&DATE($B$1,5,1),수납!$G:$G,"계좌이체") | G509: =SUMIFS(수납!$F:$F,수납!$A:$A,">="&DATE($B$1,5,1),수납!$A:$A,"<"&DATE($B$1,6,1),수납!$G:$G,"계좌이체") | H509: =SUMIFS(수납!$F:$F,수납!$A:$A,">="&DATE($B$1,6,1),수납!$A:$A,"<"&DATE($B$1,7,1),수납!$G:$G,"계좌이체") | I509: =SUMIFS(수납!$F:$F,수납!$A:$A,">="&DATE($B$1,7,1),수납!$A:$A,"<"&DATE($B$1,8,1),수납!$G:$G,"계좌이체") | J509: =SUMIFS(수납!$F:$F,수납!$A:$A,">="&DATE($B$1,8,1),수납!$A:$A,"<"&DATE($B$1,9,1),수납!$G:$G,"계좌이체") | K509: =SUMIFS(수납!$F:$F,수납!$A:$A,">="&DATE($B$1,9,1),수납!$A:$A,"<"&DATE($B$1,10,1),수납!$G:$G,"계좌이체") | L509: =SUMIFS(수납!$F:$F,수납!$A:$A,">="&DATE($B$1,10,1),수납!$A:$A,"<"&DATE($B$1,11,1),수납!$G:$G,"계좌이체") | M509: =SUMIFS(수납!$F:$F,수납!$A:$A,">="&DATE($B$1,11,1),수납!$A:$A,"<"&DATE($B$1,12,1),수납!$G:$G,"계좌이체") | N509: =SUMIFS(수납!$F:$F,수납!$A:$A,">="&DATE($B$1,12,1),수납!$A:$A,"<"&DATE($B$1+1,1,1),수납!$G:$G,"계좌이체")
A510: 현금 | C510: =SUMIFS(수납!$F:$F,수납!$A:$A,">="&DATE($B$1,1,1),수납!$A:$A,"<"&DATE($B$1,2,1),수납!$G:$G,"현금") | D510: =SUMIFS(수납!$F:$F,수납!$A:$A,">="&DATE($B$1,2,1),수납!$A:$A,"<"&DATE($B$1,3,1),수납!$G:$G,"현금") | E510: =SUMIFS(수납!$F:$F,수납!$A:$A,">="&DATE($B$1,3,1),수납!$A:$A,"<"&DATE($B$1,4,1),수납!$G:$G,"현금") | F510: =SUMIFS(수납!$F:$F,수납!$A:$A,">="&DATE($B$1,4,1),수납!$A:$A,"<"&DATE($B$1,5,1),수납!$G:$G,"현금") | G510: =SUMIFS(수납!$F:$F,수납!$A:$A,">="&DATE($B$1,5,1),수납!$A:$A,"<"&DATE($B$1,6,1),수납!$G:$G,"현금") | H510: =SUMIFS(수납!$F:$F,수납!$A:$A,">="&DATE($B$1,6,1),수납!$A:$A,"<"&DATE($B$1,7,1),수납!$G:$G,"현금") | I510: =SUMIFS(수납!$F:$F,수납!$A:$A,">="&DATE($B$1,7,1),수납!$A:$A,"<"&DATE($B$1,8,1),수납!$G:$G,"현금") | J510: =SUMIFS(수납!$F:$F,수납!$A:$A,">="&DATE($B$1,8,1),수납!$A:$A,"<"&DATE($B$1,9,1),수납!$G:$G,"현금") | K510: =SUMIFS(수납!$F:$F,수납!$A:$A,">="&DATE($B$1,9,1),수납!$A:$A,"<"&DATE($B$1,10,1),수납!$G:$G,"현금") | L510: =SUMIFS(수납!$F:$F,수납!$A:$A,">="&DATE($B$1,10,1),수납!$A:$A,"<"&DATE($B$1,11,1),수납!$G:$G,"현금") | M510: =SUMIFS(수납!$F:$F,수납!$A:$A,">="&DATE($B$1,11,1),수납!$A:$A,"<"&DATE($B$1,12,1),수납!$G:$G,"현금") | N510: =SUMIFS(수납!$F:$F,수납!$A:$A,">="&DATE($B$1,12,1),수납!$A:$A,"<"&DATE($B$1+1,1,1),수납!$G:$G,"현금")
A511: 합계 | C511: =SUM(C508:C510) | D511: =SUM(D508:D510) | E511: =SUM(E508:E510) | F511: =SUM(F508:F510) | G511: =SUM(G508:G510) | H511: =SUM(H508:H510) | I511: =SUM(I508:I510) | J511: =SUM(J508:J510) | ... N511: =SUM(N508:N510)
A512: 덜 받은 원생 수 | C512: =IF(DATE($B$1,1,1)>TODAY(),"",SUM(P4:P503)) | D512: =IF(DATE($B$1,2,1)>TODAY(),"",SUM(Q4:Q503)) | E512: =IF(DATE($B$1,3,1)>TODAY(),"",SUM(R4:R503)) | F512: =IF(DATE($B$1,4,1)>TODAY(),"",SUM(S4:S503)) | G512: =IF(DATE($B$1,5,1)>TODAY(),"",SUM(T4:T503)) | H512: =IF(DATE($B$1,6,1)>TODAY(),"",SUM(U4:U503)) | I512: =IF(DATE($B$1,7,1)>TODAY(),"",SUM(V4:V503)) | J512: =IF(DATE($B$1,8,1)>TODAY(),"",SUM(W4:W503)) | K512: =IF(DATE($B$1,9,1)>TODAY(),"",SUM(X4:X503)) | L512: =IF(DATE($B$1,10,1)>TODAY(),"",SUM(Y4:Y503)) | M512: =IF(DATE($B$1,11,1)>TODAY(),"",SUM(Z4:Z503)) | N512: =IF(DATE($B$1,12,1)>TODAY(),"",SUM(AA4:AA503))

Sheet 계산
A1: 원생 열쇠 | B1: 수강월 | C1: 수강료 | E1: 원생 시트 열쇠
A2: =IF(수납!$C2="","",수납!$C2&"|"&IF(수납!$D2<>"",수납!$D2,IF(COUNTIF(원생!$A$2:$A$501,수납!$C2)=1,INDEX(원생!$G$2:$G$501,MATCH(수납!$C2,원생!$A$2:$A$501,0))&"",""))) | B2: =IFERROR(IF(수납!$B2="",YEAR(수납!$A2)*100+MONTH(수납!$A2),IF(ISNUMBER(수납!$B2),YEAR(수납!$B2)*100+MONTH(수납!$B2),VALUE(LEFT(수납!$B2,4))*100+VALUE(MID(수납!$B2,6,2)))),"") | C2: =IF(OR(수납!$E2="수강료",수납!$E2=""),N(수납!$F2),0) | E2: =IF(원생!$A2="","",원생!$A2&"|"&원생!$G2)
A3: =IF(수납!$C3="","",수납!$C3&"|"&IF(수납!$D3<>"",수납!$D3,IF(COUNTIF(원생!$A$2:$A$501,수납!$C3)=1,INDEX(원생!$G$2:$G$501,MATCH(수납!$C3,원생!$A$2:$A$501,0))&"",""))) | B3: =IFERROR(IF(수납!$B3="",YEAR(수납!$A3)*100+MONTH(수납!$A3),IF(ISNUMBER(수납!$B3),YEAR(수납!$B3)*100+MONTH(수납!$B3),VALUE(LEFT(수납!$B3,4))*100+VALUE(MID(수납!$B3,6,2)))),"") | C3: =IF(OR(수납!$E3="수강료",수납!$E3=""),N(수납!$F3),0) | E3: =IF(원생!$A3="","",원생!$A3&"|"&원생!$G3)
A4: =IF(수납!$C4="","",수납!$C4&"|"&IF(수납!$D4<>"",수납!$D4,IF(COUNTIF(원생!$A$2:$A$501,수납!$C4)=1,INDEX(원생!$G$2:$G$501,MATCH(수납!$C4,원생!$A$2:$A$501,0))&"",""))) | B4: =IFERROR(IF(수납!$B4="",YEAR(수납!$A4)*100+MONTH(수납!$A4),IF(ISNUMBER(수납!$B4),YEAR(수납!$B4)*100+MONTH(수납!$B4),VALUE(LEFT(수납!$B4,4))*100+VALUE(MID(수납!$B4,6,2)))),"") | C4: =IF(OR(수납!$E4="수강료",수납!$E4=""),N(수납!$F4),0) | E4: =IF(원생!$A4="","",원생!$A4&"|"&원생!$G4)
A5: =IF(수납!$C5="","",수납!$C5&"|"&IF(수납!$D5<>"",수납!$D5,IF(COUNTIF(원생!$A$2:$A$501,수납!$C5)=1,INDEX(원생!$G$2:$G$501,MATCH(수납!$C5,원생!$A$2:$A$501,0))&"",""))) | B5: =IFERROR(IF(수납!$B5="",YEAR(수납!$A5)*100+MONTH(수납!$A5),IF(ISNUMBER(수납!$B5),YEAR(수납!$B5)*100+MONTH(수납!$B5),VALUE(LEFT(수납!$B5,4))*100+VALUE(MID(수납!$B5,6,2)))),"") | C5: =IF(OR(수납!$E5="수강료",수납!$E5=""),N(수납!$F5),0) | E5: =IF(원생!$A5="","",원생!$A5&"|"&원생!$G5)
A6: =IF(수납!$C6="","",수납!$C6&"|"&IF(수납!$D6<>"",수납!$D6,IF(COUNTIF(원생!$A$2:$A$501,수납!$C6)=1,INDEX(원생!$G$2:$G$501,MATCH(수납!$C6,원생!$A$2:$A$501,0))&"",""))) | B6: =IFERROR(IF(수납!$B6="",YEAR(수납!$A6)*100+MONTH(수납!$A6),IF(ISNUMBER(수납!$B6),YEAR(수납!$B6)*100+MONTH(수납!$B6),VALUE(LEFT(수납!$B6,4))*100+VALUE(MID(수납!$B6,6,2)))),"") | C6: =IF(OR(수납!$E6="수강료",수납!$E6=""),N(수납!$F6),0) | E6: =IF(원생!$A6="","",원생!$A6&"|"&원생!$G6)
A7: =IF(수납!$C7="","",수납!$C7&"|"&IF(수납!$D7<>"",수납!$D7,IF(COUNTIF(원생!$A$2:$A$501,수납!$C7)=1,INDEX(원생!$G$2:$G$501,MATCH(수납!$C7,원생!$A$2:$A$501,0))&"",""))) | B7: =IFERROR(IF(수납!$B7="",YEAR(수납!$A7)*100+MONTH(수납!$A7),IF(ISNUMBER(수납!$B7),YEAR(수납!$B7)*100+MONTH(수납!$B7),VALUE(LEFT(수납!$B7,4))*100+VALUE(MID(수납!$B7,6,2)))),"") | C7: =IF(OR(수납!$E7="수강료",수납!$E7=""),N(수납!$F7),0) | E7: =IF(원생!$A7="","",원생!$A7&"|"&원생!$G7)
A8: =IF(수납!$C8="","",수납!$C8&"|"&IF(수납!$D8<>"",수납!$D8,IF(COUNTIF(원생!$A$2:$A$501,수납!$C8)=1,INDEX(원생!$G$2:$G$501,MATCH(수납!$C8,원생!$A$2:$A$501,0))&"",""))) | B8: =IFERROR(IF(수납!$B8="",YEAR(수납!$A8)*100+MONTH(수납!$A8),IF(ISNUMBER(수납!$B8),YEAR(수납!$B8)*100+MONTH(수납!$B8),VALUE(LEFT(수납!$B8,4))*100+VALUE(MID(수납!$B8,6,2)))),"") | C8: =IF(OR(수납!$E8="수강료",수납!$E8=""),N(수납!$F8),0) | E8: =IF(원생!$A8="","",원생!$A8&"|"&원생!$G8)
A9: =IF(수납!$C9="","",수납!$C9&"|"&IF(수납!$D9<>"",수납!$D9,IF(COUNTIF(원생!$A$2:$A$501,수납!$C9)=1,INDEX(원생!$G$2:$G$501,MATCH(수납!$C9,원생!$A$2:$A$501,0))&"",""))) | B9: =IFERROR(IF(수납!$B9="",YEAR(수납!$A9)*100+MONTH(수납!$A9),IF(ISNUMBER(수납!$B9),YEAR(수납!$B9)*100+MONTH(수납!$B9),VALUE(LEFT(수납!$B9,4))*100+VALUE(MID(수납!$B9,6,2)))),"") | C9: =IF(OR(수납!$E9="수강료",수납!$E9=""),N(수납!$F9),0) | E9: =IF(원생!$A9="","",원생!$A9&"|"&원생!$G9)
A10: =IF(수납!$C10="","",수납!$C10&"|"&IF(수납!$D10<>"",수납!$D10,IF(COUNTIF(원생!$A$2:$A$501,수납!$C10)=1,INDEX(원생!$G$2:$G$501,MATCH(수납!$C10,원생!$A$2:$A$501,0))&"",""))) | B10: =IFERROR(IF(수납!$B10="",YEAR(수납!$A10)*100+MONTH(수납!$A10),IF(ISNUMBER(수납!$B10),YEAR(수납!$B10)*100+MONTH(수납!$B10),VALUE(LEFT(수납!$B10,4))*100+VALUE(MID(수납!$B10,6,2)))),"") | C10: =IF(OR(수납!$E10="수강료",수납!$E10=""),N(수납!$F10),0) | E10: =IF(원생!$A10="","",원생!$A10&"|"&원생!$G10)
A11: =IF(수납!$C11="","",수납!$C11&"|"&IF(수납!$D11<>"",수납!$D11,IF(COUNTIF(원생!$A$2:$A$501,수납!$C11)=1,INDEX(원생!$G$2:$G$501,MATCH(수납!$C11,원생!$A$2:$A$501,0))&"",""))) | B11: =IFERROR(IF(수납!$B11="",YEAR(수납!$A11)*100+MONTH(수납!$A11),IF(ISNUMBER(수납!$B11),YEAR(수납!$B11)*100+MONTH(수납!$B11),VALUE(LEFT(수납!$B11,4))*100+VALUE(MID(수납!$B11,6,2)))),"") | C11: =IF(OR(수납!$E11="수강료",수납!$E11=""),N(수납!$F11),0) | E11: =IF(원생!$A11="","",원생!$A11&"|"&원생!$G11)
A12: =IF(수납!$C12="","",수납!$C12&"|"&IF(수납!$D12<>"",수납!$D12,IF(COUNTIF(원생!$A$2:$A$501,수납!$C12)=1,INDEX(원생!$G$2:$G$501,MATCH(수납!$C12,원생!$A$2:$A$501,0))&"",""))) | B12: =IFERROR(IF(수납!$B12="",YEAR(수납!$A12)*100+MONTH(수납!$A12),IF(ISNUMBER(수납!$B12),YEAR(수납!$B12)*100+MONTH(수납!$B12),VALUE(LEFT(수납!$B12,4))*100+VALUE(MID(수납!$B12,6,2)))),"") | C12: =IF(OR(수납!$E12="수강료",수납!$E12=""),N(수납!$F12),0) | E12: =IF(원생!$A12="","",원생!$A12&"|"&원생!$G12)
A13: =IF(수납!$C13="","",수납!$C13&"|"&IF(수납!$D13<>"",수납!$D13,IF(COUNTIF(원생!$A$2:$A$501,수납!$C13)=1,INDEX(원생!$G$2:$G$501,MATCH(수납!$C13,원생!$A$2:$A$501,0))&"",""))) | B13: =IFERROR(IF(수납!$B13="",YEAR(수납!$A13)*100+MONTH(수납!$A13),IF(ISNUMBER(수납!$B13),YEAR(수납!$B13)*100+MONTH(수납!$B13),VALUE(LEFT(수납!$B13,4))*100+VALUE(MID(수납!$B13,6,2)))),"") | C13: =IF(OR(수납!$E13="수강료",수납!$E13=""),N(수납!$F13),0) | E13: =IF(원생!$A13="","",원생!$A13&"|"&원생!$G13)
... A501: =IF(수납!$C501="","",수납!$C501&"|"&IF(수납!$D501<>"",수납!$D501,IF(COUNTIF(원생!$A$2:$A$501,수납!$C501)=1,INDEX(원생!$G$2:$G$501,MATCH(수납!$C501,원생!$A$2:$A$501,0))&"",""))) | B501: =IFERROR(IF(수납!$B501="",YEAR(수납!$A501)*100+MONTH(수납!$A501),IF(ISNUMBER(수납!$B501),YEAR(수납!$B501)*100+MONTH(수납!$B501),VALUE(LEFT(수납!$B501,4))*100+VALUE(MID(수납!$B501,6,2)))),"") | C501: =IF(OR(수납!$E501="수강료",수납!$E501=""),N(수납!$F501),0) | E501: =IF(원생!$A501="","",원생!$A501&"|"&원생!$G501)
A502: =IF(수납!$C502="","",수납!$C502&"|"&IF(수납!$D502<>"",수납!$D502,IF(COUNTIF(원생!$A$2:$A$501,수납!$C502)=1,INDEX(원생!$G$2:$G$501,MATCH(수납!$C502,원생!$A$2:$A$501,0))&"",""))) | B502: =IFERROR(IF(수납!$B502="",YEAR(수납!$A502)*100+MONTH(수납!$A502),IF(ISNUMBER(수납!$B502),YEAR(수납!$B502)*100+MONTH(수납!$B502),VALUE(LEFT(수납!$B502,4))*100+VALUE(MID(수납!$B502,6,2)))),"") | C502: =IF(OR(수납!$E502="수강료",수납!$E502=""),N(수납!$F502),0)
A503: =IF(수납!$C503="","",수납!$C503&"|"&IF(수납!$D503<>"",수납!$D503,IF(COUNTIF(원생!$A$2:$A$501,수납!$C503)=1,INDEX(원생!$G$2:$G$501,MATCH(수납!$C503,원생!$A$2:$A$501,0))&"",""))) | B503: =IFERROR(IF(수납!$B503="",YEAR(수납!$A503)*100+MONTH(수납!$A503),IF(ISNUMBER(수납!$B503),YEAR(수납!$B503)*100+MONTH(수납!$B503),VALUE(LEFT(수납!$B503,4))*100+VALUE(MID(수납!$B503,6,2)))),"") | C503: =IF(OR(수납!$E503="수강료",수납!$E503=""),N(수납!$F503),0)
A504: =IF(수납!$C504="","",수납!$C504&"|"&IF(수납!$D504<>"",수납!$D504,IF(COUNTIF(원생!$A$2:$A$501,수납!$C504)=1,INDEX(원생!$G$2:$G$501,MATCH(수납!$C504,원생!$A$2:$A$501,0))&"",""))) | B504: =IFERROR(IF(수납!$B504="",YEAR(수납!$A504)*100+MONTH(수납!$A504),IF(ISNUMBER(수납!$B504),YEAR(수납!$B504)*100+MONTH(수납!$B504),VALUE(LEFT(수납!$B504,4))*100+VALUE(MID(수납!$B504,6,2)))),"") | C504: =IF(OR(수납!$E504="수강료",수납!$E504=""),N(수납!$F504),0)
A505: =IF(수납!$C505="","",수납!$C505&"|"&IF(수납!$D505<>"",수납!$D505,IF(COUNTIF(원생!$A$2:$A$501,수납!$C505)=1,INDEX(원생!$G$2:$G$501,MATCH(수납!$C505,원생!$A$2:$A$501,0))&"",""))) | B505: =IFERROR(IF(수납!$B505="",YEAR(수납!$A505)*100+MONTH(수납!$A505),IF(ISNUMBER(수납!$B505),YEAR(수납!$B505)*100+MONTH(수납!$B505),VALUE(LEFT(수납!$B505,4))*100+VALUE(MID(수납!$B505,6,2)))),"") | C505: =IF(OR(수납!$E505="수강료",수납!$E505=""),N(수납!$F505),0)
A506: =IF(수납!$C506="","",수납!$C506&"|"&IF(수납!$D506<>"",수납!$D506,IF(COUNTIF(원생!$A$2:$A$501,수납!$C506)=1,INDEX(원생!$G$2:$G$501,MATCH(수납!$C506,원생!$A$2:$A$501,0))&"",""))) | B506: =IFERROR(IF(수납!$B506="",YEAR(수납!$A506)*100+MONTH(수납!$A506),IF(ISNUMBER(수납!$B506),YEAR(수납!$B506)*100+MONTH(수납!$B506),VALUE(LEFT(수납!$B506,4))*100+VALUE(MID(수납!$B506,6,2)))),"") | C506: =IF(OR(수납!$E506="수강료",수납!$E506=""),N(수납!$F506),0)
A507: =IF(수납!$C507="","",수납!$C507&"|"&IF(수납!$D507<>"",수납!$D507,IF(COUNTIF(원생!$A$2:$A$501,수납!$C507)=1,INDEX(원생!$G$2:$G$501,MATCH(수납!$C507,원생!$A$2:$A$501,0))&"",""))) | B507: =IFERROR(IF(수납!$B507="",YEAR(수납!$A507)*100+MONTH(수납!$A507),IF(ISNUMBER(수납!$B507),YEAR(수납!$B507)*100+MONTH(수납!$B507),VALUE(LEFT(수납!$B507,4))*100+VALUE(MID(수납!$B507,6,2)))),"") | C507: =IF(OR(수납!$E507="수강료",수납!$E507=""),N(수납!$F507),0)
A508: =IF(수납!$C508="","",수납!$C508&"|"&IF(수납!$D508<>"",수납!$D508,IF(COUNTIF(원생!$A$2:$A$501,수납!$C508)=1,INDEX(원생!$G$2:$G$501,MATCH(수납!$C508,원생!$A$2:$A$501,0))&"",""))) | B508: =IFERROR(IF(수납!$B508="",YEAR(수납!$A508)*100+MONTH(수납!$A508),IF(ISNUMBER(수납!$B508),YEAR(수납!$B508)*100+MONTH(수납!$B508),VALUE(LEFT(수납!$B508,4))*100+VALUE(MID(수납!$B508,6,2)))),"") | C508: =IF(OR(수납!$E508="수강료",수납!$E508=""),N(수납!$F508),0)
A509: =IF(수납!$C509="","",수납!$C509&"|"&IF(수납!$D509<>"",수납!$D509,IF(COUNTIF(원생!$A$2:$A$501,수납!$C509)=1,INDEX(원생!$G$2:$G$501,MATCH(수납!$C509,원생!$A$2:$A$501,0))&"",""))) | B509: =IFERROR(IF(수납!$B509="",YEAR(수납!$A509)*100+MONTH(수납!$A509),IF(ISNUMBER(수납!$B509),YEAR(수납!$B509)*100+MONTH(수납!$B509),VALUE(LEFT(수납!$B509,4))*100+VALUE(MID(수납!$B509,6,2)))),"") | C509: =IF(OR(수납!$E509="수강료",수납!$E509=""),N(수납!$F509),0)
